Workbook

Sheet Resumen
A1: PINCH LAB
A2: Integración energética · Cp constante · Contracorriente · División de corrientes por intervalos
A3: ='Entradas'!A7 -> Datos válidos
A5: Calor disponible | B5: =SUMIFS('Entradas'!$F$11:$F$14,'Entradas'!$E$11:$E$14,"HOT") -> 530000 | C5: kJ/h
A6: Demanda de calor | B6: =SUMIFS('Entradas'!$F$11:$F$14,'Entradas'!$E$11:$E$14,"COLD") -> 540000 | C6: kJ/h
A7: Calentamiento mínimo | B7: =MAX(0,-MIN('Cascada'!H4:H11)) -> 70000 | C7: kJ/h
A8: Refrigeración mínima | B8: ='Cascada'!H11+B7 -> 60000 | C8: kJ/h
A9: Calor recuperado | B9: =B5-B8 -> 470000 | C9: kJ/h
A10: Demanda cubierta | B10: =IF(B6=0,0,B9/B6) -> 0.87037037
A11: ΔT mínimo | B11: ='Entradas'!B4 -> 10 | C11: K
A12: Balance global | B12: =B5+B7-B6-B8 -> 0 | C12: kJ/h
A14: Tolerancia numérica | B14: =MAX(1,B5,B6)*0.000000001 -> 0.00054 | C14: kJ/h
A16: Equipos de proceso | B16: =COUNTIFS('Equipos'!E4:E183,">"&B14) -> 22
A18: Conversión a kW
A19: Calentamiento | B19: =B7/3600 -> 19.444444 | C19: kW
A20: Refrigeración | B20: =B8/3600 -> 16.666667 | C20: kW
A21: Recuperación | B21: =B9/3600 -> 130.55556 | C21: kW
A24: Para editar: Entradas, celdas azules. El pinch es un resultado. Encontrarás todos sus nodos en Cascada, columnas J:L. En umbrales o zonas pinch puede haber varios nodos.
A30: Red ideal de máxima recuperación con ramas y mezclas a igual temperatura. No minimiza equipos ni costes. Área solo si introduces U. Servicios externos sin temperaturas especificadas: se calcula su carga, no su área.
A36: Cambiar el número de corrientes requiere regenerar el Excel desde Python. En este libro sí puedes cambiar ID, CP, Tin, Tout, ΔT y U. No insertes filas dentro de los cálculos.
A42: Calor sensible y CP constante por corriente. Para cp variable, discretiza por intervalos. No introducir cambios de fase como Tin=Tout.

Sheet Entradas
A1: Datos del proceso
A2: Edita las celdas azules. CP = caudal × calor específico. Unidades originales del PDF.
A4: ΔT mínimo (K) | B4: 10
A5: U (kJ/h·m²·K) | B5: 0 | C5: U=0: área sin calcular. U no viene en el PDF; introduce tu hipótesis si la conoces.
A7: =IF(AND(ISNUMBER(B4),B4>=0,ISNUMBER(B5),B5>=0,COUNT(B11:D14)=12,MIN(B11:B14)>0,MIN(C11:D14)>=-273.15,SUMPRODUCT(--(C11:C14=D11:D14))=0,COUNTA(A11:A14)=4,SUMPRODUCT(1/COUNTIF(A11:A14,A11:A14))=4),"Datos válidos","REVISAR ENTRADAS: números, CP, Tin ≠ Tout e identificadores únicos") -> Datos válidos
A8: Fuente: PDF aportado · Synthesis of Heat Exchanger Networks · diapositivas 27 y 30. H1/H2/C3/C4 corresponden a 1/2/3/4.
A10: ID | B10: CP (kJ/h·K) | C10: Tin (°C) | D10: Tout (°C) | E10: Tipo calculado | F10: |Q| (kJ/h) | G10: Q con signo | H10: T baja | I10: T alta | J10: T* baja | K10: T* alta
A11: H1 | B11: 1000 | C11: 250 | D11: 120 | E11: =IF(C11>D11,"HOT",IF(C11<D11,"COLD","ERROR")) -> HOT | F11: =B11*ABS(C11-D11) -> 130000 | G11: =B11*(C11-D11) -> 130000 | H11: =MIN(C11,D11) -> 120 | I11: =MAX(C11,D11) -> 250 | J11: =H11+IF(E11="HOT",-$B$4/2,$B$4/2) -> 115 | K11: =I11+IF(E11="HOT",-$B$4/2,$B$4/2) -> 245
A12: H2 | B12: 4000 | C12: 200 | D12: 100 | E12: =IF(C12>D12,"HOT",IF(C12<D12,"COLD","ERROR")) -> HOT | F12: =B12*ABS(C12-D12) -> 400000 | G12: =B12*(C12-D12) -> 400000 | H12: =MIN(C12,D12) -> 100 | I12: =MAX(C12,D12) -> 200 | J12: =H12+IF(E12="HOT",-$B$4/2,$B$4/2) -> 95 | K12: =I12+IF(E12="HOT",-$B$4/2,$B$4/2) -> 195
A13: C3 | B13: 3000 | C13: 90 | D13: 150 | E13: =IF(C13>D13,"HOT",IF(C13<D13,"COLD","ERROR")) -> COLD | F13: =B13*ABS(C13-D13) -> 180000 | G13: =B13*(C13-D13) -> -180000 | H13: =MIN(C13,D13) -> 90 | I13: =MAX(C13,D13) -> 150 | J13: =H13+IF(E13="HOT",-$B$4/2,$B$4/2) -> 95 | K13: =I13+IF(E13="HOT",-$B$4/2,$B$4/2) -> 155
A14: C4 | B14: 6000 | C14: 130 | D14: 190 | E14: =IF(C14>D14,"HOT",IF(C14<D14,"COLD","ERROR")) -> COLD | F14: =B14*ABS(C14-D14) -> 360000 | G14: =B14*(C14-D14) -> -360000 | H14: =MIN(C14,D14) -> 130 | I14: =MAX(C14,D14) -> 190 | J14: =H14+IF(E14="HOT",-$B$4/2,$B$4/2) -> 135 | K14: =I14+IF(E14="HOT",-$B$4/2,$B$4/2) -> 195

Sheet Matriz_Q
A1: Intercambios entre corrientes
A2: Q en kJ/h. Filas: donantes calientes. Columnas: receptoras frías. La matriz suma todos los tramos.
A3: Donante / receptora | B3: ='Entradas'!A11 -> H1 | C3: ='Entradas'!A12 -> H2 | D3: ='Entradas'!A13 -> C3 | E3: ='Entradas'!A14 -> C4 | F3: Refrigeración | G3: Calentamiento | H3: |Q| corriente | I3: Error balance
A4: ='Entradas'!A11 -> H1 | B4: =SUMPRODUCT('Tramos_red'!$M$4:$M$18,'Tramos_red'!$T$4:$T$18,'Tramos_red'!$X$4:$X$18) -> 0 | C4: =SUMPRODUCT('Tramos_red'!$M$4:$M$18,'Tramos_red'!$T$4:$T$18,'Tramos_red'!$Y$4:$Y$18) -> 0 | D4: =SUMPRODUCT('Tramos_red'!$M$4:$M$18,'Tramos_red'!$T$4:$T$18,'Tramos_red'!$Z$4:$Z$18) -> 32000 | E4: =SUMPRODUCT('Tramos_red'!$M$4:$M$18,'Tramos_red'!$T$4:$T$18,'Tramos_red'!$AA$4:$AA$18) -> 98000 | F4: =SUMPRODUCT('Tramos_red'!$N$4:$N$18,'Tramos_red'!$T$4:$T$18) -> 0 | G4: =SUMPRODUCT('Tramos_red'!$O$4:$O$18,'Tramos_red'!$X$4:$X$18) -> 0 | H4: ='Entradas'!F11 -> 130000 | I4: =IF('Entradas'!E11="HOT",SUM(B4:E4)+F4,SUM(B$4:B$7)+G4)-H4 -> 0
A5: ='Entradas'!A12 -> H2 | B5: =SUMPRODUCT('Tramos_red'!$M$4:$M$18,'Tramos_red'!$U$4:$U$18,'Tramos_red'!$X$4:$X$18) -> 0 | C5: =SUMPRODUCT('Tramos_red'!$M$4:$M$18,'Tramos_red'!$U$4:$U$18,'Tramos_red'!$Y$4:$Y$18) -> 0 | D5: =SUMPRODUCT('Tramos_red'!$M$4:$M$18,'Tramos_red'!$U$4:$U$18,'Tramos_red'!$Z$4:$Z$18) -> 148000 | E5: =SUMPRODUCT('Tramos_red'!$M$4:$M$18,'Tramos_red'!$U$4:$U$18,'Tramos_red'!$AA$4:$AA$18) -> 192000 | F5: =SUMPRODUCT('Tramos_red'!$N$4:$N$18,'Tramos_red'!$U$4:$U$18) -> 60000 | G5: =SUMPRODUCT('Tramos_red'!$O$4:$O$18,'Tramos_red'!$Y$4:$Y$18) -> 0 | H5: ='Entradas'!F12 -> 400000 | I5: =IF('Entradas'!E12="HOT",SUM(B5:E5)+F5,SUM(C$4:C$7)+G5)-H5 -> 0
A6: ='Entradas'!A13 -> C3 | B6: =SUMPRODUCT('Tramos_red'!$M$4:$M$18,'Tramos_red'!$V$4:$V$18,'Tramos_red'!$X$4:$X$18) -> 0 | C6: =SUMPRODUCT('Tramos_red'!$M$4:$M$18,'Tramos_red'!$V$4:$V$18,'Tramos_red'!$Y$4:$Y$18) -> 0 | D6: =SUMPRODUCT('Tramos_red'!$M$4:$M$18,'Tramos_red'!$V$4:$V$18,'Tramos_red'!$Z$4:$Z$18) -> 0 | E6: =SUMPRODUCT('Tramos_red'!$M$4:$M$18,'Tramos_red'!$V$4:$V$18,'Tramos_red'!$AA$4:$AA$18) -> 0 | F6: =SUMPRODUCT('Tramos_red'!$N$4:$N$18,'Tramos_red'!$V$4:$V$18) -> 0 | G6: =SUMPRODUCT('Tramos_red'!$O$4:$O$18,'Tramos_red'!$Z$4:$Z$18) -> 0 | H6: ='Entradas'!F13 -> 180000 | I6: =IF('Entradas'!E13="HOT",SUM(B6:E6)+F6,SUM(D$4:D$7)+G6)-H6 -> 0
A7: ='Entradas'!A14 -> C4 | B7: =SUMPRODUCT('Tramos_red'!$M$4:$M$18,'Tramos_red'!$W$4:$W$18,'Tramos_red'!$X$4:$X$18) -> 0 | C7: =SUMPRODUCT('Tramos_red'!$M$4:$M$18,'Tramos_red'!$W$4:$W$18,'Tramos_red'!$Y$4:$Y$18) -> 0 | D7: =SUMPRODUCT('Tramos_red'!$M$4:$M$18,'Tramos_red'!$W$4:$W$18,'Tramos_red'!$Z$4:$Z$18) -> 0 | E7: =SUMPRODUCT('Tramos_red'!$M$4:$M$18,'Tramos_red'!$W$4:$W$18,'Tramos_red'!$AA$4:$AA$18) -> 0 | F7: =SUMPRODUCT('Tramos_red'!$N$4:$N$18,'Tramos_red'!$W$4:$W$18) -> 0 | G7: =SUMPRODUCT('Tramos_red'!$O$4:$O$18,'Tramos_red'!$AA$4:$AA$18) -> 70000 | H7: ='Entradas'!F14 -> 360000 | I7: =IF('Entradas'!E14="HOT",SUM(B7:E7)+F7,SUM(E$4:E$7)+G7)-H7 -> 0

Sheet Equipos
A1: Intercambiadores de ramas
A2: Filtra Q > 0 para ver los equipos activos. Si cambias entradas, vuelve a aplicar el filtro. Las fracciones se refieren a cada corriente original.
A3: ID candidato | B3: Tramo | C3: Caliente | D3: Fría | E3: Q (kJ/h) | F3: Th entrada | G3: Th salida | H3: Tc entrada | I3: Tc salida | J3: Rama hot | K3: Rama cold | L3: CP rama hot | M3: CP rama cold | N3: ΔT extremo 1 | O3: ΔT extremo 2 | P3: ΔT log media | Q3: Área (m²)
A4: B1-P1-2 | B4: 1 | C4: ='Entradas'!A11 -> H1 | D4: ='Entradas'!A12 -> H2 | E4: ='Tramos_red'!M4*'Tramos_red'!T4*'Tramos_red'!Y4 -> 0 | F4: =IF(E4>'Resumen'!$B$14,'Tramos_red'!J4,"") | G4: =IF(E4>'Resumen'!$B$14,'Tramos_red'!I4,"") | H4: =IF(E4>'Resumen'!$B$14,'Tramos_red'!K4,"") | I4: =IF(E4>'Resumen'!$B$14,'Tramos_red'!L4,"") | J4: =IF(E4>'Resumen'!$B$14,'Tramos_red'!Y4,0) -> 0 | K4: =IF(E4>'Resumen'!$B$14,'Tramos_red'!T4,0) -> 0 | L4: =J4*'Entradas'!B11 -> 0 | M4: =K4*'Entradas'!B12 -> 0 | N4: =IF(E4>'Resumen'!$B$14,'Tramos_red'!P4,0) -> 0 | O4: =IF(E4>'Resumen'!$B$14,'Tramos_red'!Q4,0) -> 0 | P4: =IF(E4>'Resumen'!$B$14,'Tramos_red'!R4,0) -> 0 | Q4: =IF(E4<='Resumen'!$B$14,0,IF('Entradas'!$B$5=0,"sin U",IF(P4=0,"infinita",E4/('Entradas'!$B$5*P4)))) -> 0
A5: B1-P1-3 | B5: 1 | C5: ='Entradas'!A11 -> H1 | D5: ='Entradas'!A13 -> C3 | E5: ='Tramos_red'!M4*'Tramos_red'!T4*'Tramos_red'!Z4 -> 0 | F5: =IF(E5>'Resumen'!$B$14,'Tramos_red'!J4,"") | G5: =IF(E5>'Resumen'!$B$14,'Tramos_red'!I4,"") | H5: =IF(E5>'Resumen'!$B$14,'Tramos_red'!K4,"") | I5: =IF(E5>'Resumen'!$B$14,'Tramos_red'!L4,"") | J5: =IF(E5>'Resumen'!$B$14,'Tramos_red'!Z4,0) -> 0 | K5: =IF(E5>'Resumen'!$B$14,'Tramos_red'!T4,0) -> 0 | L5: =J5*'Entradas'!B11 -> 0 | M5: =K5*'Entradas'!B13 -> 0 | N5: =IF(E5>'Resumen'!$B$14,'Tramos_red'!P4,0) -> 0 | O5: =IF(E5>'Resumen'!$B$14,'Tramos_red'!Q4,0) -> 0 | P5: =IF(E5>'Resumen'!$B$14,'Tramos_red'!R4,0) -> 0 | Q5: =IF(E5<='Resumen'!$B$14,0,IF('Entradas'!$B$5=0,"sin U",IF(P5=0,"infinita",E5/('Entradas'!$B$5*P5)))) -> 0
A6: B1-P1-4 | B6: 1 | C6: ='Entradas'!A11 -> H1 | D6: ='Entradas'!A14 -> C4 | E6: ='Tramos_red'!M4*'Tramos_red'!T4*'Tramos_red'!AA4 -> 0 | F6: =IF(E6>'Resumen'!$B$14,'Tramos_red'!J4,"") | G6: =IF(E6>'Resumen'!$B$14,'Tramos_red'!I4,"") | H6: =IF(E6>'Resumen'!$B$14,'Tramos_red'!K4,"") | I6: =IF(E6>'Resumen'!$B$14,'Tramos_red'!L4,"") | J6: =IF(E6>'Resumen'!$B$14,'Tramos_red'!AA4,0) -> 0 | K6: =IF(E6>'Resumen'!$B$14,'Tramos_red'!T4,0) -> 0 | L6: =J6*'Entradas'!B11 -> 0 | M6: =K6*'Entradas'!B14 -> 0 | N6: =IF(E6>'Resumen'!$B$14,'Tramos_red'!P4,0) -> 0 | O6: =IF(E6>'Resumen'!$B$14,'Tramos_red'!Q4,0) -> 0 | P6: =IF(E6>'Resumen'!$B$14,'Tramos_red'!R4,0) -> 0 | Q6: =IF(E6<='Resumen'!$B$14,0,IF('Entradas'!$B$5=0,"sin U",IF(P6=0,"infinita",E6/('Entradas'!$B$5*P6)))) -> 0
A7: B1-P2-1 | B7: 1 | C7: ='Entradas'!A12 -> H2 | D7: ='Entradas'!A11 -> H1 | E7: ='Tramos_red'!M4*'Tramos_red'!U4*'Tramos_red'!X4 -> 0 | F7: =IF(E7>'Resumen'!$B$14,'Tramos_red'!J4,"") | G7: =IF(E7>'Resumen'!$B$14,'Tramos_red'!I4,"") | H7: =IF(E7>'Resumen'!$B$14,'Tramos_red'!K4,"") | I7: =IF(E7>'Resumen'!$B$14,'Tramos_red'!L4,"") | J7: =IF(E7>'Resumen'!$B$14,'Tramos_red'!X4,0) -> 0 | K7: =IF(E7>'Resumen'!$B$14,'Tramos_red'!U4,0) -> 0 | L7: =J7*'Entradas'!B12 -> 0 | M7: =K7*'Entradas'!B11 -> 0 | N7: =IF(E7>'Resumen'!$B$14,'Tramos_red'!P4,0) -> 0 | O7: =IF(E7>'Resumen'!$B$14,'Tramos_red'!Q4,0) -> 0 | P7: =IF(E7>'Resumen'!$B$14,'Tramos_red'!R4,0) -> 0 | Q7: =IF(E7<='Resumen'!$B$14,0,IF('Entradas'!$B$5=0,"sin U",IF(P7=0,"infinita",E7/('Entradas'!$B$5*P7)))) -> 0
A8: B1-P2-3 | B8: 1 | C8: ='Entradas'!A12 -> H2 | D8: ='Entradas'!A13 -> C3 | E8: ='Tramos_red'!M4*'Tramos_red'!U4*'Tramos_red'!Z4 -> 0 | F8: =IF(E8>'Resumen'!$B$14,'Tramos_red'!J4,"") | G8: =IF(E8>'Resumen'!$B$14,'Tramos_red'!I4,"") | H8: =IF(E8>'Resumen'!$B$14,'Tramos_red'!K4,"") | I8: =IF(E8>'Resumen'!$B$14,'Tramos_red'!L4,"") | J8: =IF(E8>'Resumen'!$B$14,'Tramos_red'!Z4,0) -> 0 | K8: =IF(E8>'Resumen'!$B$14,'Tramos_red'!U4,0) -> 0 | L8: =J8*'Entradas'!B12 -> 0 | M8: =K8*'Entradas'!B13 -> 0 | N8: =IF(E8>'Resumen'!$B$14,'Tramos_red'!P4,0) -> 0 | O8: =IF(E8>'Resumen'!$B$14,'Tramos_red'!Q4,0) -> 0 | P8: =IF(E8>'Resumen'!$B$14,'Tramos_red'!R4,0) -> 0 | Q8: =IF(E8<='Resumen'!$B$14,0,IF('Entradas'!$B$5=0,"sin U",IF(P8=0,"infinita",E8/('Entradas'!$B$5*P8)))) -> 0
A9: B1-P2-4 | B9: 1 | C9: ='Entradas'!A12 -> H2 | D9: ='Entradas'!A14 -> C4 | E9: ='Tramos_red'!M4*'Tramos_red'!U4*'Tramos_red'!AA4 -> 0 | F9: =IF(E9>'Resumen'!$B$14,'Tramos_red'!J4,"") | G9: =IF(E9>'Resumen'!$B$14,'Tramos_red'!I4,"") | H9: =IF(E9>'Resumen'!$B$14,'Tramos_red'!K4,"") | I9: =IF(E9>'Resumen'!$B$14,'Tramos_red'!L4,"") | J9: =IF(E9>'Resumen'!$B$14,'Tramos_red'!AA4,0) -> 0 | K9: =IF(E9>'Resumen'!$B$14,'Tramos_red'!U4,0) -> 0 | L9: =J9*'Entradas'!B12 -> 0 | M9: =K9*'Entradas'!B14 -> 0 | N9: =IF(E9>'Resumen'!$B$14,'Tramos_red'!P4,0) -> 0 | O9: =IF(E9>'Resumen'!$B$14,'Tramos_red'!Q4,0) -> 0 | P9: =IF(E9>'Resumen'!$B$14,'Tramos_red'!R4,0) -> 0 | Q9: =IF(E9<='Resumen'!$B$14,0,IF('Entradas'!$B$5=0,"sin U",IF(P9=0,"infinita",E9/('Entradas'!$B$5*P9)))) -> 0
A10: B1-P3-1 | B10: 1 | C10: ='Entradas'!A13 -> C3 | D10: ='Entradas'!A11 -> H1 | E10: ='Tramos_red'!M4*'Tramos_red'!V4*'Tramos_red'!X4 -> 0 | F10: =IF(E10>'Resumen'!$B$14,'Tramos_red'!J4,"") | G10: =IF(E10>'Resumen'!$B$14,'Tramos_red'!I4,"") | H10: =IF(E10>'Resumen'!$B$14,'Tramos_red'!K4,"") | I10: =IF(E10>'Resumen'!$B$14,'Tramos_red'!L4,"") | J10: =IF(E10>'Resumen'!$B$14,'Tramos_red'!X4,0) -> 0 | K10: =IF(E10>'Resumen'!$B$14,'Tramos_red'!V4,0) -> 0 | L10: =J10*'Entradas'!B13 -> 0 | M10: =K10*'Entradas'!B11 -> 0 | N10: =IF(E10>'Resumen'!$B$14,'Tramos_red'!P4,0) -> 0 | O10: =IF(E10>'Resumen'!$B$14,'Tramos_red'!Q4,0) -> 0 | P10: =IF(E10>'Resumen'!$B$14,'Tramos_red'!R4,0) -> 0 | Q10: =IF(E10<='Resumen'!$B$14,0,IF('Entradas'!$B$5=0,"sin U",IF(P10=0,"infinita",E10/('Entradas'!$B$5*P10)))) -> 0
A11: B1-P3-2 | B11: 1 | C11: ='Entradas'!A13 -> C3 | D11: ='Entradas'!A12 -> H2 | E11: ='Tramos_red'!M4*'Tramos_red'!V4*'Tramos_red'!Y4 -> 0 | F11: =IF(E11>'Resumen'!$B$14,'Tramos_red'!J4,"") | G11: =IF(E11>'Resumen'!$B$14,'Tramos_red'!I4,"") | H11: =IF(E11>'Resumen'!$B$14,'Tramos_red'!K4,"") | I11: =IF(E11>'Resumen'!$B$14,'Tramos_red'!L4,"") | J11: =IF(E11>'Resumen'!$B$14,'Tramos_red'!Y4,0) -> 0 | K11: =IF(E11>'Resumen'!$B$14,'Tramos_red'!V4,0) -> 0 | L11: =J11*'Entradas'!B13 -> 0 | M11: =K11*'Entradas'!B12 -> 0 | N11: =IF(E11>'Resumen'!$B$14,'Tramos_red'!P4,0) -> 0 | O11: =IF(E11>'Resumen'!$B$14,'Tramos_red'!Q4,0) -> 0 | P11: =IF(E11>'Resumen'!$B$14,'Tramos_red'!R4,0) -> 0 | Q11: =IF(E11<='Resumen'!$B$14,0,IF('Entradas'!$B$5=0,"sin U",IF(P11=0,"infinita",E11/('Entradas'!$B$5*P11)))) -> 0
A12: B1-P3-4 | B12: 1 | C12: ='Entradas'!A13 -> C3 | D12: ='Entradas'!A14 -> C4 | E12: ='Tramos_red'!M4*'Tramos_red'!V4*'Tramos_red'!AA4 -> 0 | F12: =IF(E12>'Resumen'!$B$14,'Tramos_red'!J4,"") | G12: =IF(E12>'Resumen'!$B$14,'Tramos_red'!I4,"") | H12: =IF(E12>'Resumen'!$B$14,'Tramos_red'!K4,"") | I12: =IF(E12>'Resumen'!$B$14,'Tramos_red'!L4,"") | J12: =IF(E12>'Resumen'!$B$14,'Tramos_red'!AA4,0) -> 0 | K12: =IF(E12>'Resumen'!$B$14,'Tramos_red'!V4,0) -> 0 | L12: =J12*'Entradas'!B13 -> 0 | M12: =K12*'Entradas'!B14 -> 0 | N12: =IF(E12>'Resumen'!$B$14,'Tramos_red'!P4,0) -> 0 | O12: =IF(E12>'Resumen'!$B$14,'Tramos_red'!Q4,0) -> 0 | P12: =IF(E12>'Resumen'!$B$14,'Tramos_red'!R4,0) -> 0 | Q12: =IF(E12<='Resumen'!$B$14,0,IF('Entradas'!$B$5=0,"sin U",IF(P12=0,"infinita",E12/('Entradas'!$B$5*P12)))) -> 0
A13: B1-P4-1 | B13: 1 | C13: ='Entradas'!A14 -> C4 | D13: ='Entradas'!A11 -> H1 | E13: ='Tramos_red'!M4*'Tramos_red'!W4*'Tramos_red'!X4 -> 0 | F13: =IF(E13>'Resumen'!$B$14,'Tramos_red'!J4,"") | G13: =IF(E13>'Resumen'!$B$14,'Tramos_red'!I4,"") | H13: =IF(E13>'Resumen'!$B$14,'Tramos_red'!K4,"") | I13: =IF(E13>'Resumen'!$B$14,'Tramos_red'!L4,"") | J13: =IF(E13>'Resumen'!$B$14,'Tramos_red'!X4,0) -> 0 | K13: =IF(E13>'Resumen'!$B$14,'Tramos_red'!W4,0) -> 0 | L13: =J13*'Entradas'!B14 -> 0 | M13: =K13*'Entradas'!B11 -> 0 | N13: =IF(E13>'Resumen'!$B$14,'Tramos_red'!P4,0) -> 0 | O13: =IF(E13>'Resumen'!$B$14,'Tramos_red'!Q4,0) -> 0 | P13: =IF(E13>'Resumen'!$B$14,'Tramos_red'!R4,0) -> 0 | Q13: =IF(E13<='Resumen'!$B$14,0,IF('Entradas'!$B$5=0,"sin U",IF(P13=0,"infinita",E13/('Entradas'!$B$5*P13)))) -> 0
A14: B1-P4-2 | B14: 1 | C14: ='Entradas'!A14 -> C4 | D14: ='Entradas'!A12 -> H2 | E14: ='Tramos_red'!M4*'Tramos_red'!W4*'Tramos_red'!Y4 -> 0 | F14: =IF(E14>'Resumen'!$B$14,'Tramos_red'!J4,"") | G14: =IF(E14>'Resumen'!$B$14,'Tramos_red'!I4,"") | H14: =IF(E14>'Resumen'!$B$14,'Tramos_red'!K4,"") | I14: =IF(E14>'Resumen'!$B$14,'Tramos_red'!L4,"") | J14: =IF(E14>'Resumen'!$B$14,'Tramos_red'!Y4,0) -> 0 | K14: =IF(E14>'Resumen'!$B$14,'Tramos_red'!W4,0) -> 0 | L14: =J14*'Entradas'!B14 -> 0 | M14: =K14*'Entradas'!B12 -> 0 | N14: =IF(E14>'Resumen'!$B$14,'Tramos_red'!P4,0) -> 0 | O14: =IF(E14>'Resumen'!$B$14,'Tramos_red'!Q4,0) -> 0 | P14: =IF(E14>'Resumen'!$B$14,'Tramos_red'!R4,0) -> 0 | Q14: =IF(E14<='Resumen'!$B$14,0,IF('Entradas'!$B$5=0,"sin U",IF(P14=0,"infinita",E14/('Entradas'!$B$5*P14)))) -> 0
A15: B1-P4-3 | B15: 1 | C15: ='Entradas'!A14 -> C4 | D15: ='Entradas'!A13 -> C3 | E15: ='Tramos_red'!M4*'Tramos_red'!W4*'Tramos_red'!Z4 -> 0 | F15: =IF(E15>'Resumen'!$B$14,'Tramos_red'!J4,"") | G15: =IF(E15>'Resumen'!$B$14,'Tramos_red'!I4,"") | H15: =IF(E15>'Resumen'!$B$14,'Tramos_red'!K4,"") | I15: =IF(E15>'Resumen'!$B$14,'Tramos_red'!L4,"") | J15: =IF(E15>'Resumen'!$B$14,'Tramos_red'!Z4,0) -> 0 | K15: =IF(E15>'Resumen'!$B$14,'Tramos_red'!W4,0) -> 0 | L15: =J15*'Entradas'!B14 -> 0 | M15: =K15*'Entradas'!B13 -> 0 | N15: =IF(E15>'Resumen'!$B$14,'Tramos_red'!P4,0) -> 0 | O15: =IF(E15>'Resumen'!$B$14,'Tramos_red'!Q4,0) -> 0 | P15: =IF(E15>'Resumen'!$B$14,'Tramos_red'!R4,0) -> 0 | Q15: =IF(E15<='Resumen'!$B$14,0,IF('Entradas'!$B$5=0,"sin U",IF(P15=0,"infinita",E15/('Entradas'!$B$5*P15)))) -> 0
A16: B2-P1-2 | B16: 2 | C16: ='Entradas'!A11 -> H1 | D16: ='Entradas'!A12 -> H2 | E16: ='Tramos_red'!M5*'Tramos_red'!T5*'Tramos_red'!Y5 -> 0 | F16: =IF(E16>'Resumen'!$B$14,'Tramos_red'!J5,"") | G16: =IF(E16>'Resumen'!$B$14,'Tramos_red'!I5,"") | H16: =IF(E16>'Resumen'!$B$14,'Tramos_red'!K5,"") | I16: =IF(E16>'Resumen'!$B$14,'Tramos_red'!L5,"") | J16: =IF(E16>'Resumen'!$B$14,'Tramos_red'!Y5,0) -> 0 | K16: =IF(E16>'Resumen'!$B$14,'Tramos_red'!T5,0) -> 0 | L16: =J16*'Entradas'!B11 -> 0 | M16: =K16*'Entradas'!B12 -> 0 | N16: =IF(E16>'Resumen'!$B$14,'Tramos_red'!P5,0) -> 0 | O16: =IF(E16>'Resumen'!$B$14,'Tramos_red'!Q5,0) -> 0 | P16: =IF(E16>'Resumen'!$B$14,'Tramos_red'!R5,0) -> 0 | Q16: =IF(E16<='Resumen'!$B$14,0,IF('Entradas'!$B$5=0,"sin U",IF(P16=0,"infinita",E16/('Entradas'!$B$5*P16)))) -> 0
A17: B2-P1-3 | B17: 2 | C17: ='Entradas'!A11 -> H1 | D17: ='Entradas'!A13 -> C3 | E17: ='Tramos_red'!M5*'Tramos_red'!T5*'Tramos_red'!Z5 -> 0 | F17: =IF(E17>'Resumen'!$B$14,'Tramos_red'!J5,"") | G17: =IF(E17>'Resumen'!$B$14,'Tramos_red'!I5,"") | H17: =IF(E17>'Resumen'!$B$14,'Tramos_red'!K5,"") | I17: =IF(E17>'Resumen'!$B$14,'Tramos_red'!L5,"") | J17: =IF(E17>'Resumen'!$B$14,'Tramos_red'!Z5,0) -> 0 | K17: =IF(E17>'Resumen'!$B$14,'Tramos_red'!T5,0) -> 0 | L17: =J17*'Entradas'!B11 -> 0 | M17: =K17*'Entradas'!B13 -> 0 | N17: =IF(E17>'Resumen'!$B$14,'Tramos_red'!P5,0) -> 0 | O17: =IF(E17>'Resumen'!$B$14,'Tramos_red'!Q5,0) -> 0 | P17: =IF(E17>'Resumen'!$B$14,'Tramos_red'!R5,0) -> 0 | Q17: =IF(E17<='Resumen'!$B$14,0,IF('Entradas'!$B$5=0,"sin U",IF(P17=0,"infinita",E17/('Entradas'!$B$5*P17)))) -> 0
A18: B2-P1-4 | B18: 2 | C18: ='Entradas'!A11 -> H1 | D18: ='Entradas'!A14 -> C4 | E18: ='Tramos_red'!M5*'Tramos_red'!T5*'Tramos_red'!AA5 -> 0 | F18: =IF(E18>'Resumen'!$B$14,'Tramos_red'!J5,"") | G18: =IF(E18>'Resumen'!$B$14,'Tramos_red'!I5,"") | H18: =IF(E18>'Resumen'!$B$14,'Tramos_red'!K5,"") | I18: =IF(E18>'Resumen'!$B$14,'Tramos_red'!L5,"") | J18: =IF(E18>'Resumen'!$B$14,'Tramos_red'!AA5,0) -> 0 | K18: =IF(E18>'Resumen'!$B$14,'Tramos_red'!T5,0) -> 0 | L18: =J18*'Entradas'!B11 -> 0 | M18: =K18*'Entradas'!B14 -> 0 | N18: =IF(E18>'Resumen'!$B$14,'Tramos_red'!P5,0) -> 0 | O18: =IF(E18>'Resumen'!$B$14,'Tramos_red'!Q5,0) -> 0 | P18: =IF(E18>'Resumen'!$B$14,'Tramos_red'!R5,0) -> 0 | Q18: =IF(E18<='Resumen'!$B$14,0,IF('Entradas'!$B$5=0,"sin U",IF(P18=0,"infinita",E18/('Entradas'!$B$5*P18)))) -> 0
A19: B2-P2-1 | B19: 2 | C19: ='Entradas'!A12 -> H2 | D19: ='Entradas'!A11 -> H1 | E19: ='Tramos_red'!M5*'Tramos_red'!U5*'Tramos_red'!X5 -> 0 | F19: =IF(E19>'Resumen'!$B$14,'Tramos_red'!J5,"") | G19: =IF(E19>'Resumen'!$B$14,'Tramos_red'!I5,"") | H19: =IF(E19>'Resumen'!$B$14,'Tramos_red'!K5,"") | I19: =IF(E19>'Resumen'!$B$14,'Tramos_red'!L5,"") | J19: =IF(E19>'Resumen'!$B$14,'Tramos_red'!X5,0) -> 0 | K19: =IF(E19>'Resumen'!$B$14,'Tramos_red'!U5,0) -> 0 | L19: =J19*'Entradas'!B12 -> 0 | M19: =K19*'Entradas'!B11 -> 0 | N19: =IF(E19>'Resumen'!$B$14,'Tramos_red'!P5,0) -> 0 | O19: =IF(E19>'Resumen'!$B$14,'Tramos_red'!Q5,0) -> 0 | P19: =IF(E19>'Resumen'!$B$14,'Tramos_red'!R5,0) -> 0 | Q19: =IF(E19<='Resumen'!$B$14,0,IF('Entradas'!$B$5=0,"sin U",IF(P19=0,"infinita",E19/('Entradas'!$B$5*P19)))) -> 0
A20: B2-P2-3 | B20: 2 | C20: ='Entradas'!A12 -> H2 | D20: ='Entradas'!A13 -> C3 | E20: ='Tramos_red'!M5*'Tramos_red'!U5*'Tramos_red'!Z5 -> 0 | F20: =IF(E20>'Resumen'!$B$14,'Tramos_red'!J5,"") | G20: =IF(E20>'Resumen'!$B$14,'Tramos_red'!I5,"") | H20: =IF(E20>'Resumen'!$B$14,'Tramos_red'!K5,"") | I20: =IF(E20>'Resumen'!$B$14,'Tramos_red'!L5,"") | J20: =IF(E20>'Resumen'!$B$14,'Tramos_red'!Z5,0) -> 0 | K20: =IF(E20>'Resumen'!$B$14,'Tramos_red'!U5,0) -> 0 | L20: =J20*'Entradas'!B12 -> 0 | M20: =K20*'Entradas'!B13 -> 0 | N20: =IF(E20>'Resumen'!$B$14,'Tramos_red'!P5,0) -> 0 | O20: =IF(E20>'Resumen'!$B$14,'Tramos_red'!Q5,0) -> 0 | P20: =IF(E20>'Resumen'!$B$14,'Tramos_red'!R5,0) -> 0 | Q20: =IF(E20<='Resumen'!$B$14,0,IF('Entradas'!$B$5=0,"sin U",IF(P20=0,"infinita",E20/('Entradas'!$B$5*P20)))) -> 0
A21: B2-P2-4 | B21: 2 | C21: ='Entradas'!A12 -> H2 | D21: ='Entradas'!A14 -> C4 | E21: ='Tramos_red'!M5*'Tramos_red'!U5*'Tramos_red'!AA5 -> 0 | F21: =IF(E21>'Resumen'!$B$14,'Tramos_red'!J5,"") | G21: =IF(E21>'Resumen'!$B$14,'Tramos_red'!I5,"") | H21: =IF(E21>'Resumen'!$B$14,'Tramos_red'!K5,"") | I21: =IF(E21>'Resumen'!$B$14,'Tramos_red'!L5,"") | J21: =IF(E21>'Resumen'!$B$14,'Tramos_red'!AA5,0) -> 0 | K21: =IF(E21>'Resumen'!$B$14,'Tramos_red'!U5,0) -> 0 | L21: =J21*'Entradas'!B12 -> 0 | M21: =K21*'Entradas'!B14 -> 0 | N21: =IF(E21>'Resumen'!$B$14,'Tramos_red'!P5,0) -> 0 | O21: =IF(E21>'Resumen'!$B$14,'Tramos_red'!Q5,0) -> 0 | P21: =IF(E21>'Resumen'!$B$14,'Tramos_red'!R5,0) -> 0 | Q21: =IF(E21<='Resumen'!$B$14,0,IF('Entradas'!$B$5=0,"sin U",IF(P21=0,"infinita",E21/('Entradas'!$B$5*P21)))) -> 0
A22: B2-P3-1 | B22: 2 | C22: ='Entradas'!A13 -> C3 | D22: ='Entradas'!A11 -> H1 | E22: ='Tramos_red'!M5*'Tramos_red'!V5*'Tramos_red'!X5 -> 0 | F22: =IF(E22>'Resumen'!$B$14,'Tramos_red'!J5,"") | G22: =IF(E22>'Resumen'!$B$14,'Tramos_red'!I5,"") | H22: =IF(E22>'Resumen'!$B$14,'Tramos_red'!K5,"") | I22: =IF(E22>'Resumen'!$B$14,'Tramos_red'!L5,"") | J22: =IF(E22>'Resumen'!$B$14,'Tramos_red'!X5,0) -> 0 | K22: =IF(E22>'Resumen'!$B$14,'Tramos_red'!V5,0) -> 0 | L22: =J22*'Entradas'!B13 -> 0 | M22: =K22*'Entradas'!B11 -> 0 | N22: =IF(E22>'Resumen'!$B$14,'Tramos_red'!P5,0) -> 0 | O22: =IF(E22>'Resumen'!$B$14,'Tramos_red'!Q5,0) -> 0 | P22: =IF(E22>'Resumen'!$B$14,'Tramos_red'!R5,0) -> 0 | Q22: =IF(E22<='Resumen'!$B$14,0,IF('Entradas'!$B$5=0,"sin U",IF(P22=0,"infinita",E22/('Entradas'!$B$5*P22)))) -> 0
A23: B2-P3-2 | B23: 2 | C23: ='Entradas'!A13 -> C3 | D23: ='Entradas'!A12 -> H2 | E23: ='Tramos_red'!M5*'Tramos_red'!V5*'Tramos_red'!Y5 -> 0 | F23: =IF(E23>'Resumen'!$B$14,'Tramos_red'!J5,"") | G23: =IF(E23>'Resumen'!$B$14,'Tramos_red'!I5,"") | H23: =IF(E23>'Resumen'!$B$14,'Tramos_red'!K5,"") | I23: =IF(E23>'Resumen'!$B$14,'Tramos_red'!L5,"") | J23: =IF(E23>'Resumen'!$B$14,'Tramos_red'!Y5,0) -> 0 | K23: =IF(E23>'Resumen'!$B$14,'Tramos_red'!V5,0) -> 0 | L23: =J23*'Entradas'!B13 -> 0 | M23: =K23*'Entradas'!B12 -> 0 | N23: =IF(E23>'Resumen'!$B$14,'Tramos_red'!P5,0) -> 0 | O23: =IF(E23>'Resumen'!$B$14,'Tramos_red'!Q5,0) -> 0 | P23: =IF(E23>'Resumen'!$B$14,'Tramos_red'!R5,0) -> 0 | Q23: =IF(E23<='Resumen'!$B$14,0,IF('Entradas'!$B$5=0,"sin U",IF(P23=0,"infinita",E23/('Entradas'!$B$5*P23)))) -> 0
A24: B2-P3-4 | B24: 2 | C24: ='Entradas'!A13 -> C3 | D24: ='Entradas'!A14 -> C4 | E24: ='Tramos_red'!M5*'Tramos_red'!V5*'Tramos_red'!AA5 -> 0 | F24: =IF(E24>'Resumen'!$B$14,'Tramos_red'!J5,"") | G24: =IF(E24>'Resumen'!$B$14,'Tramos_red'!I5,"") | H24: =IF(E24>'Resumen'!$B$14,'Tramos_red'!K5,"") | I24: =IF(E24>'Resumen'!$B$14,'Tramos_red'!L5,"") | J24: =IF(E24>'Resumen'!$B$14,'Tramos_red'!AA5,0) -> 0 | K24: =IF(E24>'Resumen'!$B$14,'Tramos_red'!V5,0) -> 0 | L24: =J24*'Entradas'!B13 -> 0 | M24: =K24*'Entradas'!B14 -> 0 | N24: =IF(E24>'Resumen'!$B$14,'Tramos_red'!P5,0) -> 0 | O24: =IF(E24>'Resumen'!$B$14,'Tramos_red'!Q5,0) -> 0 | P24: =IF(E24>'Resumen'!$B$14,'Tramos_red'!R5,0) -> 0 | Q24: =IF(E24<='Resumen'!$B$14,0,IF('Entradas'!$B$5=0,"sin U",IF(P24=0,"infinita",E24/('Entradas'!$B$5*P24)))) -> 0
A25: B2-P4-1 | B25: 2 | C25: ='Entradas'!A14 -> C4 | D25: ='Entradas'!A11 -> H1 | E25: ='Tramos_red'!M5*'Tramos_red'!W5*'Tramos_red'!X5 -> 0 | F25: =IF(E25>'Resumen'!$B$14,'Tramos_red'!J5,"") | G25: =IF(E25>'Resumen'!$B$14,'Tramos_red'!I5,"") | H25: =IF(E25>'Resumen'!$B$14,'Tramos_red'!K5,"") | I25: =IF(E25>'Resumen'!$B$14,'Tramos_red'!L5,"") | J25: =IF(E25>'Resumen'!$B$14,'Tramos_red'!X5,0) -> 0 | K25: =IF(E25>'Resumen'!$B$14,'Tramos_red'!W5,0) -> 0 | L25: =J25*'Entradas'!B14 -> 0 | M25: =K25*'Entradas'!B11 -> 0 | N25: =IF(E25>'Resumen'!$B$14,'Tramos_red'!P5,0) -> 0 | O25: =IF(E25>'Resumen'!$B$14,'Tramos_red'!Q5,0) -> 0 | P25: =IF(E25>'Resumen'!$B$14,'Tramos_red'!R5,0) -> 0 | Q25: =IF(E25<='Resumen'!$B$14,0,IF('Entradas'!$B$5=0,"sin U",IF(P25=0,"infinita",E25/('Entradas'!$B$5*P25)))) -> 0
A26: B2-P4-2 | B26: 2 | C26: ='Entradas'!A14 -> C4 | D26: ='Entradas'!A12 -> H2 | E26: ='Tramos_red'!M5*'Tramos_red'!W5*'Tramos_red'!Y5 -> 0 | F26: =IF(E26>'Resumen'!$B$14,'Tramos_red'!J5,"") | G26: =IF(E26>'Resumen'!$B$14,'Tramos_red'!I5,"") | H26: =IF(E26>'Resumen'!$B$14,'Tramos_red'!K5,"") | I26: =IF(E26>'Resumen'!$B$14,'Tramos_red'!L5,"") | J26: =IF(E26>'Resumen'!$B$14,'Tramos_red'!Y5,0) -> 0 | K26: =IF(E26>'Resumen'!$B$14,'Tramos_red'!W5,0) -> 0 | L26: =J26*'Entradas'!B14 -> 0 | M26: =K26*'Entradas'!B12 -> 0 | N26: =IF(E26>'Resumen'!$B$14,'Tramos_red'!P5,0) -> 0 | O26: =IF(E26>'Resumen'!$B$14,'Tramos_red'!Q5,0) -> 0 | P26: =IF(E26>'Resumen'!$B$14,'Tramos_red'!R5,0) -> 0 | Q26: =IF(E26<='Resumen'!$B$14,0,IF('Entradas'!$B$5=0,"sin U",IF(P26=0,"infinita",E26/('Entradas'!$B$5*P26)))) -> 0
A27: B2-P4-3 | B27: 2 | C27: ='Entradas'!A14 -> C4 | D27: ='Entradas'!A13 -> C3 | E27: ='Tramos_red'!M5*'Tramos_red'!W5*'Tramos_red'!Z5 -> 0 | F27: =IF(E27>'Resumen'!$B$14,'Tramos_red'!J5,"") | G27: =IF(E27>'Resumen'!$B$14,'Tramos_red'!I5,"") | H27: =IF(E27>'Resumen'!$B$14,'Tramos_red'!K5,"") | I27: =IF(E27>'Resumen'!$B$14,'Tramos_red'!L5,"") | J27: =IF(E27>'Resumen'!$B$14,'Tramos_red'!Z5,0) -> 0 | K27: =IF(E27>'Resumen'!$B$14,'Tramos_red'!W5,0) -> 0 | L27: =J27*'Entradas'!B14 -> 0 | M27: =K27*'Entradas'!B13 -> 0 | N27: =IF(E27>'Resumen'!$B$14,'Tramos_red'!P5,0) -> 0 | O27: =IF(E27>'Resumen'!$B$14,'Tramos_red'!Q5,0) -> 0 | P27: =IF(E27>'Resumen'!$B$14,'Tramos_red'!R5,0) -> 0 | Q27: =IF(E27<='Resumen'!$B$14,0,IF('Entradas'!$B$5=0,"sin U",IF(P27=0,"infinita",E27/('Entradas'!$B$5*P27)))) -> 0
A28: B3-P1-2 | B28: 3 | C28: ='Entradas'!A11 -> H1 | D28: ='Entradas'!A12 -> H2 | E28: ='Tramos_red'!M6*'Tramos_red'!T6*'Tramos_red'!Y6 -> 0 | F28: =IF(E28>'Resumen'!$B$14,'Tramos_red'!J6,"") | G28: =IF(E28>'Resumen'!$B$14,'Tramos_red'!I6,"") | H28: =IF(E28>'Resumen'!$B$14,'Tramos_red'!K6,"") | I28: =IF(E28>'Resumen'!$B$14,'Tramos_red'!L6,"") | J28: =IF(E28>'Resumen'!$B$14,'Tramos_red'!Y6,0) -> 0 | K28: =IF(E28>'Resumen'!$B$14,'Tramos_red'!T6,0) -> 0 | L28: =J28*'Entradas'!B11 -> 0 | M28: =K28*'Entradas'!B12 -> 0 | N28: =IF(E28>'Resumen'!$B$14,'Tramos_red'!P6,0) -> 0 | O28: =IF(E28>'Resumen'!$B$14,'Tramos_red'!Q6,0) -> 0 | P28: =IF(E28>'Resumen'!$B$14,'Tramos_red'!R6,0) -> 0 | Q28: =IF(E28<='Resumen'!$B$14,0,IF('Entradas'!$B$5=0,"sin U",IF(P28=0,"infinita",E28/('Entradas'!$B$5*P28)))) -> 0
A29: B3-P1-3 | B29: 3 | C29: ='Entradas'!A11 -> H1 | D29: ='Entradas'!A13 -> C3 | E29: ='Tramos_red'!M6*'Tramos_red'!T6*'Tramos_red'!Z6 -> 0 | F29: =IF(E29>'Resumen'!$B$14,'Tramos_red'!J6,"") | G29: =IF(E29>'Resumen'!$B$14,'Tramos_red'!I6,"") | H29: =IF(E29>'Resumen'!$B$14,'Tramos_red'!K6,"") | I29: =IF(E29>'Resumen'!$B$14,'Tramos_red'!L6,"") | J29: =IF(E29>'Resumen'!$B$14,'Tramos_red'!Z6,0) -> 0 | K29: =IF(E29>'Resumen'!$B$14,'Tramos_red'!T6,0) -> 0 | L29: =J29*'Entradas'!B11 -> 0 | M29: =K29*'Entradas'!B13 -> 0 | N29: =IF(E29>'Resumen'!$B$14,'Tramos_red'!P6,0) -> 0 | O29: =IF(E29>'Resumen'!$B$14,'Tramos_red'!Q6,0) -> 0 | P29: =IF(E29>'Resumen'!$B$14,'Tramos_red'!R6,0) -> 0 | Q29: =IF(E29<='Resumen'!$B$14,0,IF('Entradas'!$B$5=0,"sin U",IF(P29=0,"infinita",E29/('Entradas'!$B$5*P29)))) -> 0
A30: B3-P1-4 | B30: 3 | C30: ='Entradas'!A11 -> H1 | D30: ='Entradas'!A14 -> C4 | E30: ='Tramos_red'!M6*'Tramos_red'!T6*'Tramos_red'!AA6 -> 0 | F30: =IF(E30>'Resumen'!$B$14,'Tramos_red'!J6,"") | G30: =IF(E30>'Resumen'!$B$14,'Tramos_red'!I6,"") | H30: =IF(E30>'Resumen'!$B$14,'Tramos_red'!K6,"") | I30: =IF(E30>'Resumen'!$B$14,'Tramos_red'!L6,"") | J30: =IF(E30>'Resumen'!$B$14,'Tramos_red'!AA6,0) -> 0 | K30: =IF(E30>'Resumen'!$B$14,'Tramos_red'!T6,0) -> 0 | L30: =J30*'Entradas'!B11 -> 0 | M30: =K30*'Entradas'!B14 -> 0 | N30: =IF(E30>'Resumen'!$B$14,'Tramos_red'!P6,0) -> 0 | O30: =IF(E30>'Resumen'!$B$14,'Tramos_red'!Q6,0) -> 0 | P30: =IF(E30>'Resumen'!$B$14,'Tramos_red'!R6,0) -> 0 | Q30: =IF(E30<='Resumen'!$B$14,0,IF('Entradas'!$B$5=0,"sin U",IF(P30=0,"infinita",E30/('Entradas'!$B$5*P30)))) -> 0
A31: B3-P2-1 | B31: 3 | C31: ='Entradas'!A12 -> H2 | D31: ='Entradas'!A11 -> H1 | E31: ='Tramos_red'!M6*'Tramos_red'!U6*'Tramos_red'!X6 -> 0 | F31: =IF(E31>'Resumen'!$B$14,'Tramos_red'!J6,"") | G31: =IF(E31>'Resumen'!$B$14,'Tramos_red'!I6,"") | H31: =IF(E31>'Resumen'!$B$14,'Tramos_red'!K6,"") | I31: =IF(E31>'Resumen'!$B$14,'Tramos_red'!L6,"") | J31: =IF(E31>'Resumen'!$B$14,'Tramos_red'!X6,0) -> 0 | K31: =IF(E31>'Resumen'!$B$14,'Tramos_red'!U6,0) -> 0 | L31: =J31*'Entradas'!B12 -> 0 | M31: =K31*'Entradas'!B11 -> 0 | N31: =IF(E31>'Resumen'!$B$14,'Tramos_red'!P6,0) -> 0 | O31: =IF(E31>'Resumen'!$B$14,'Tramos_red'!Q6,0) -> 0 | P31: =IF(E31>'Resumen'!$B$14,'Tramos_red'!R6,0) -> 0 | Q31: =IF(E31<='Resumen'!$B$14,0,IF('Entradas'!$B$5=0,"sin U",IF(P31=0,"infinita",E31/('Entradas'!$B$5*P31)))) -> 0
A32: B3-P2-3 | B32: 3 | C32: ='Entradas'!A12 -> H2 | D32: ='Entradas'!A13 -> C3 | E32: ='Tramos_red'!M6*'Tramos_red'!U6*'Tramos_red'!Z6 -> 20000 | F32: =IF(E32>'Resumen'!$B$14,'Tramos_red'!J6,"") -> 120 | G32: =IF(E32>'Resumen'!$B$14,'Tramos_red'!I6,"") -> 115 | H32: =IF(E32>'Resumen'!$B$14,'Tramos_red'!K6,"") -> 90 | I32: =IF(E32>'Resumen'!$B$14,'Tramos_red'!L6,"") -> 96.666667 | J32: =IF(E32>'Resumen'!$B$14,'Tramos_red'!Z6,0) -> 1 | K32: =IF(E32>'Resumen'!$B$14,'Tramos_red'!U6,0) -> 1 | L32: =J32*'Entradas'!B12 -> 4000 | M32: =K32*'Entradas'!B13 -> 3000 | N32: =IF(E32>'Resumen'!$B$14,'Tramos_red'!P6,0) -> 23.333333 | O32: =IF(E32>'Resumen'!$B$14,'Tramos_red'!Q6,0) -> 25 | P32: =IF(E32>'Resumen'!$B$14,'Tramos_red'!R6,0) -> 24.157085 | Q32: =IF(E32<='Resumen'!$B$14,0,IF('Entradas'!$B$5=0,"sin U",IF(P32=0,"infinita",E32/('Entradas'!$B$5*P32)))) -> sin U
A33: B3-P2-4 | B33: 3 | C33: ='Entradas'!A12 -> H2 | D33: ='Entradas'!A14 -> C4 | E33: ='Tramos_red'!M6*'Tramos_red'!U6*'Tramos_red'!AA6 -> 0 | F33: =IF(E33>'Resumen'!$B$14,'Tramos_red'!J6,"") | G33: =IF(E33>'Resumen'!$B$14,'Tramos_red'!I6,"") | H33: =IF(E33>'Resumen'!$B$14,'Tramos_red'!K6,"") | I33: =IF(E33>'Resumen'!$B$14,'Tramos_red'!L6,"") | J33: =IF(E33>'Resumen'!$B$14,'Tramos_red'!AA6,0) -> 0 | K33: =IF(E33>'Resumen'!$B$14,'Tramos_red'!U6,0) -> 0 | L33: =J33*'Entradas'!B12 -> 0 | M33: =K33*'Entradas'!B14 -> 0 | N33: =IF(E33>'Resumen'!$B$14,'Tramos_red'!P6,0) -> 0 | O33: =IF(E33>'Resumen'!$B$14,'Tramos_red'!Q6,0) -> 0 | P33: =IF(E33>'Resumen'!$B$14,'Tramos_red'!R6,0) -> 0 | Q33: =IF(E33<='Resumen'!$B$14,0,IF('Entradas'!$B$5=0,"sin U",IF(P33=0,"infinita",E33/('Entradas'!$B$5*P33)))) -> 0
A34: B3-P3-1 | B34: 3 | C34: ='Entradas'!A13 -> C3 | D34: ='Entradas'!A11 -> H1 | E34: ='Tramos_red'!M6*'Tramos_red'!V6*'Tramos_red'!X6 -> 0 | F34: =IF(E34>'Resumen'!$B$14,'Tramos_red'!J6,"") | G34: =IF(E34>'Resumen'!$B$14,'Tramos_red'!I6,"") | H34: =IF(E34>'Resumen'!$B$14,'Tramos_red'!K6,"") | I34: =IF(E34>'Resumen'!$B$14,'Tramos_red'!L6,"") | J34: =IF(E34>'Resumen'!$B$14,'Tramos_red'!X6,0) -> 0 | K34: =IF(E34>'Resumen'!$B$14,'Tramos_red'!V6,0) -> 0 | L34: =J34*'Entradas'!B13 -> 0 | M34: =K34*'Entradas'!B11 -> 0 | N34: =IF(E34>'Resumen'!$B$14,'Tramos_red'!P6,0) -> 0 | O34: =IF(E34>'Resumen'!$B$14,'Tramos_red'!Q6,0) -> 0 | P34: =IF(E34>'Resumen'!$B$14,'Tramos_red'!R6,0) -> 0 | Q34: =IF(E34<='Resumen'!$B$14,0,IF('Entradas'!$B$5=0,"sin U",IF(P34=0,"infinita",E34/('Entradas'!$B$5*P34)))) -> 0
A35: B3-P3-2 | B35: 3 | C35: ='Entradas'!A13 -> C3 | D35: ='Entradas'!A12 -> H2 | E35: ='Tramos_red'!M6*'Tramos_red'!V6*'Tramos_red'!Y6 -> 0 | F35: =IF(E35>'Resumen'!$B$14,'Tramos_red'!J6,"") | G35: =IF(E35>'Resumen'!$B$14,'Tramos_red'!I6,"") | H35: =IF(E35>'Resumen'!$B$14,'Tramos_red'!K6,"") | I35: =IF(E35>'Resumen'!$B$14,'Tramos_red'!L6,"") | J35: =IF(E35>'Resumen'!$B$14,'Tramos_red'!Y6,0) -> 0 | K35: =IF(E35>'Resumen'!$B$14,'Tramos_red'!V6,0) -> 0 | L35: =J35*'Entradas'!B13 -> 0 | M35: =K35*'Entradas'!B12 -> 0 | N35: =IF(E35>'Resumen'!$B$14,'Tramos_red'!P6,0) -> 0 | O35: =IF(E35>'Resumen'!$B$14,'Tramos_red'!Q6,0) -> 0 | P35: =IF(E35>'Resumen'!$B$14,'Tramos_red'!R6,0) -> 0 | Q35: =IF(E35<='Resumen'!$B$14,0,IF('Entradas'!$B$5=0,"sin U",IF(P35=0,"infinita",E35/('Entradas'!$B$5*P35)))) -> 0
A36: B3-P3-4 | B36: 3 | C36: ='Entradas'!A13 -> C3 | D36: ='Entradas'!A14 -> C4 | E36: ='Tramos_red'!M6*'Tramos_red'!V6*'Tramos_red'!AA6 -> 0 | F36: =IF(E36>'Resumen'!$B$14,'Tramos_red'!J6,"") | G36: =IF(E36>'Resumen'!$B$14,'Tramos_red'!I6,"") | H36: =IF(E36>'Resumen'!$B$14,'Tramos_red'!K6,"") | I36: =IF(E36>'Resumen'!$B$14,'Tramos_red'!L6,"") | J36: =IF(E36>'Resumen'!$B$14,'Tramos_red'!AA6,0) -> 0 | K36: =IF(E36>'Resumen'!$B$14,'Tramos_red'!V6,0) -> 0 | L36: =J36*'Entradas'!B13 -> 0 | M36: =K36*'Entradas'!B14 -> 0 | N36: =IF(E36>'Resumen'!$B$14,'Tramos_red'!P6,0) -> 0 | O36: =IF(E36>'Resumen'!$B$14,'Tramos_red'!Q6,0) -> 0 | P36: =IF(E36>'Resumen'!$B$14,'Tramos_red'!R6,0) -> 0 | Q36: =IF(E36<='Resumen'!$B$14,0,IF('Entradas'!$B$5=0,"sin U",IF(P36=0,"infinita",E36/('Entradas'!$B$5*P36)))) -> 0
A37: B3-P4-1 | B37: 3 | C37: ='Entradas'!A14 -> C4 | D37: ='Entradas'!A11 -> H1 | E37: ='Tramos_red'!M6*'Tramos_red'!W6*'Tramos_red'!X6 -> 0 | F37: =IF(E37>'Resumen'!$B$14,'Tramos_red'!J6,"") | G37: =IF(E37>'Resumen'!$B$14,'Tramos_red'!I6,"") | H37: =IF(E37>'Resumen'!$B$14,'Tramos_red'!K6,"") | I37: =IF(E37>'Resumen'!$B$14,'Tramos_red'!L6,"") | J37: =IF(E37>'Resumen'!$B$14,'Tramos_red'!X6,0) -> 0 | K37: =IF(E37>'Resumen'!$B$14,'Tramos_red'!W6,0) -> 0 | L37: =J37*'Entradas'!B14 -> 0 | M37: =K37*'Entradas'!B11 -> 0 | N37: =IF(E37>'Resumen'!$B$14,'Tramos_red'!P6,0) -> 0 | O37: =IF(E37>'Resumen'!$B$14,'Tramos_red'!Q6,0) -> 0 | P37: =IF(E37>'Resumen'!$B$14,'Tramos_red'!R6,0) -> 0 | Q37: =IF(E37<='Resumen'!$B$14,0,IF('Entradas'!$B$5=0,"sin U",IF(P37=0,"infinita",E37/('Entradas'!$B$5*P37)))) -> 0
A38: B3-P4-2 | B38: 3 | C38: ='Entradas'!A14 -> C4 | D38: ='Entradas'!A12 -> H2 | E38: ='Tramos_red'!M6*'Tramos_red'!W6*'Tramos_red'!Y6 -> 0 | F38: =IF(E38>'Resumen'!$B$14,'Tramos_red'!J6,"") | G38: =IF(E38>'Resumen'!$B$14,'Tramos_red'!I6,"") | H38: =IF(E38>'Resumen'!$B$14,'Tramos_red'!K6,"") | I38: =IF(E38>'Resumen'!$B$14,'Tramos_red'!L6,"") | J38: =IF(E38>'Resumen'!$B$14,'Tramos_red'!Y6,0) -> 0 | K38: =IF(E38>'Resumen'!$B$14,'Tramos_red'!W6,0) -> 0 | L38: =J38*'Entradas'!B14 -> 0 | M38: =K38*'Entradas'!B12 -> 0 | N38: =IF(E38>'Resumen'!$B$14,'Tramos_red'!P6,0) -> 0 | O38: =IF(E38>'Resumen'!$B$14,'Tramos_red'!Q6,0) -> 0 | P38: =IF(E38>'Resumen'!$B$14,'Tramos_red'!R6,0) -> 0 | Q38: =IF(E38<='Resumen'!$B$14,0,IF('Entradas'!$B$5=0,"sin U",IF(P38=0,"infinita",E38/('Entradas'!$B$5*P38)))) -> 0
A39: B3-P4-3 | B39: 3 | C39: ='Entradas'!A14 -> C4 | D39: ='Entradas'!A13 -> C3 | E39: ='Tramos_red'!M6*'Tramos_red'!W6*'Tramos_red'!Z6 -> 0 | F39: =IF(E39>'Resumen'!$B$14,'Tramos_red'!J6,"") | G39: =IF(E39>'Resumen'!$B$14,'Tramos_red'!I6,"") | H39: =IF(E39>'Resumen'!$B$14,'Tramos_red'!K6,"") | I39: =IF(E39>'Resumen'!$B$14,'Tramos_red'!L6,"") | J39: =IF(E39>'Resumen'!$B$14,'Tramos_red'!Z6,0) -> 0 | K39: =IF(E39>'Resumen'!$B$14,'Tramos_red'!W6,0) -> 0 | L39: =J39*'Entradas'!B14 -> 0 | M39: =K39*'Entradas'!B13 -> 0 | N39: =IF(E39>'Resumen'!$B$14,'Tramos_red'!P6,0) -> 0 | O39: =IF(E39>'Resumen'!$B$14,'Tramos_red'!Q6,0) -> 0 | P39: =IF(E39>'Resumen'!$B$14,'Tramos_red'!R6,0) -> 0 | Q39: =IF(E39<='Resumen'!$B$14,0,IF('Entradas'!$B$5=0,"sin U",IF(P39=0,"infinita",E39/('Entradas'!$B$5*P39)))) -> 0
A40: B4-P1-2 | B40: 4 | C40: ='Entradas'!A11 -> H1 | D40: ='Entradas'!A12 -> H2 | E40: ='Tramos_red'!M7*'Tramos_red'!T7*'Tramos_red'!Y7 -> 0 | F40: =IF(E40>'Resumen'!$B$14,'Tramos_red'!J7,"") | G40: =IF(E40>'Resumen'!$B$14,'Tramos_red'!I7,"") | H40: =IF(E40>'Resumen'!$B$14,'Tramos_red'!K7,"") | I40: =IF(E40>'Resumen'!$B$14,'Tramos_red'!L7,"") | J40: =IF(E40>'Resumen'!$B$14,'Tramos_red'!Y7,0) -> 0 | K40: =IF(E40>'Resumen'!$B$14,'Tramos_red'!T7,0) -> 0 | L40: =J40*'Entradas'!B11 -> 0 | M40: =K40*'Entradas'!B12 -> 0 | N40: =IF(E40>'Resumen'!$B$14,'Tramos_red'!P7,0) -> 0 | O40: =IF(E40>'Resumen'!$B$14,'Tramos_red'!Q7,0) -> 0 | P40: =IF(E40>'Resumen'!$B$14,'Tramos_red'!R7,0) -> 0 | Q40: =IF(E40<='Resumen'!$B$14,0,IF('Entradas'!$B$5=0,"sin U",IF(P40=0,"infinita",E40/('Entradas'!$B$5*P40)))) -> 0
...

Sheet Cascada
A1: Tabla de intervalos y cascada
A2: T*hot=T−ΔTmin/2; T*cold=T+ΔTmin/2. Los intervalos repetidos tienen anchura cero.
A3: T* sin ordenar | B3: T* descendente | C3: ΔT intervalo | D3: ΣCP hot | E3: ΣCP cold | F3: CP neto | G3: ΔH intervalo | H3: Residual bruto | I3: Residual ajustado | J3: T* pinch | K3: Th pinch | L3: Tc pinch | M3: Posición
A4: ='Entradas'!J11 -> 115 | B4: =LARGE($A$4:$A$11,1) -> 245 | C4: =B4-B5 -> 50 | D4: =SUMPRODUCT(--('Entradas'!$E$11:$E$14="HOT"),--('Entradas'!$J$11:$J$14<=(B4+B5)/2),--('Entradas'!$K$11:$K$14 >=(B4+B5)/2),'Entradas'!$B$11:$B$14) -> 1000 | E4: =SUMPRODUCT(--('Entradas'!$E$11:$E$14="COLD"),--('Entradas'!$J$11:$J$14<=(B4+B5)/2),--('Entradas'!$K$11:$K$14 >=(B4+B5)/2),'Entradas'!$B$11:$B$14) -> 0 | F4: =D4-E4 -> 1000 | G4: =C4*F4 -> 50000 | H4: =0 -> 0 | I4: =H4+'Resumen'!$B$7 -> 70000 | J4: =IF(ABS(I4)<='Resumen'!$B$14,B4,"") | K4: =IF(ISNUMBER(J4),J4+'Entradas'!$B$4/2,"") | L4: =IF(ISNUMBER(J4),J4-'Entradas'!$B$4/2,"") | M4: =IF(ISNUMBER(J4),IF(OR(B4=$B$4,B4=$B$11),"umbral","interior"),"")
A5: ='Entradas'!K11 -> 245 | B5: =LARGE($A$4:$A$11,2) -> 195 | C5: =B5-B6 -> 0 | D5: =SUMPRODUCT(--('Entradas'!$E$11:$E$14="HOT"),--('Entradas'!$J$11:$J$14<=(B5+B6)/2),--('Entradas'!$K$11:$K$14 >=(B5+B6)/2),'Entradas'!$B$11:$B$14) -> 5000 | E5: =SUMPRODUCT(--('Entradas'!$E$11:$E$14="COLD"),--('Entradas'!$J$11:$J$14<=(B5+B6)/2),--('Entradas'!$K$11:$K$14 >=(B5+B6)/2),'Entradas'!$B$11:$B$14) -> 6000 | F5: =D5-E5 -> -1000 | G5: =C5*F5 -> 0 | H5: =H4+G4 -> 50000 | I5: =H5+'Resumen'!$B$7 -> 120000 | J5: =IF(ABS(I5)<='Resumen'!$B$14,B5,"") | K5: =IF(ISNUMBER(J5),J5+'Entradas'!$B$4/2,"") | L5: =IF(ISNUMBER(J5),J5-'Entradas'!$B$4/2,"") | M5: =IF(ISNUMBER(J5),IF(OR(B5=$B$4,B5=$B$11),"umbral","interior"),"")
A6: ='Entradas'!J12 -> 95 | B6: =LARGE($A$4:$A$11,3) -> 195 | C6: =B6-B7 -> 40 | D6: =SUMPRODUCT(--('Entradas'!$E$11:$E$14="HOT"),--('Entradas'!$J$11:$J$14<=(B6+B7)/2),--('Entradas'!$K$11:$K$14 >=(B6+B7)/2),'Entradas'!$B$11:$B$14) -> 5000 | E6: =SUMPRODUCT(--('Entradas'!$E$11:$E$14="COLD"),--('Entradas'!$J$11:$J$14<=(B6+B7)/2),--('Entradas'!$K$11:$K$14 >=(B6+B7)/2),'Entradas'!$B$11:$B$14) -> 6000 | F6: =D6-E6 -> -1000 | G6: =C6*F6 -> -40000 | H6: =H5+G5 -> 50000 | I6: =H6+'Resumen'!$B$7 -> 120000 | J6: =IF(ABS(I6)<='Resumen'!$B$14,B6,"") | K6: =IF(ISNUMBER(J6),J6+'Entradas'!$B$4/2,"") | L6: =IF(ISNUMBER(J6),J6-'Entradas'!$B$4/2,"") | M6: =IF(ISNUMBER(J6),IF(OR(B6=$B$4,B6=$B$11),"umbral","interior"),"")
A7: ='Entradas'!K12 -> 195 | B7: =LARGE($A$4:$A$11,4) -> 155 | C7: =B7-B8 -> 20 | D7: =SUMPRODUCT(--('Entradas'!$E$11:$E$14="HOT"),--('Entradas'!$J$11:$J$14<=(B7+B8)/2),--('Entradas'!$K$11:$K$14 >=(B7+B8)/2),'Entradas'!$B$11:$B$14) -> 5000 | E7: =SUMPRODUCT(--('Entradas'!$E$11:$E$14="COLD"),--('Entradas'!$J$11:$J$14<=(B7+B8)/2),--('Entradas'!$K$11:$K$14 >=(B7+B8)/2),'Entradas'!$B$11:$B$14) -> 9000 | F7: =D7-E7 -> -4000 | G7: =C7*F7 -> -80000 | H7: =H6+G6 -> 10000 | I7: =H7+'Resumen'!$B$7 -> 80000 | J7: =IF(ABS(I7)<='Resumen'!$B$14,B7,"") | K7: =IF(ISNUMBER(J7),J7+'Entradas'!$B$4/2,"") | L7: =IF(ISNUMBER(J7),J7-'Entradas'!$B$4/2,"") | M7: =IF(ISNUMBER(J7),IF(OR(B7=$B$4,B7=$B$11),"umbral","interior"),"")
A8: ='Entradas'!J13 -> 95 | B8: =LARGE($A$4:$A$11,5) -> 135 | C8: =B8-B9 -> 20 | D8: =SUMPRODUCT(--('Entradas'!$E$11:$E$14="HOT"),--('Entradas'!$J$11:$J$14<=(B8+B9)/2),--('Entradas'!$K$11:$K$14 >=(B8+B9)/2),'Entradas'!$B$11:$B$14) -> 5000 | E8: =SUMPRODUCT(--('Entradas'!$E$11:$E$14="COLD"),--('Entradas'!$J$11:$J$14<=(B8+B9)/2),--('Entradas'!$K$11:$K$14 >=(B8+B9)/2),'Entradas'!$B$11:$B$14) -> 3000 | F8: =D8-E8 -> 2000 | G8: =C8*F8 -> 40000 | H8: =H7+G7 -> -70000 | I8: =H8+'Resumen'!$B$7 -> 0 | J8: =IF(ABS(I8)<='Resumen'!$B$14,B8,"") -> 135 | K8: =IF(ISNUMBER(J8),J8+'Entradas'!$B$4/2,"") -> 140 | L8: =IF(ISNUMBER(J8),J8-'Entradas'!$B$4/2,"") -> 130 | M8: =IF(ISNUMBER(J8),IF(OR(B8=$B$4,B8=$B$11),"umbral","interior"),"") -> interior
A9: ='Entradas'!K13 -> 155 | B9: =LARGE($A$4:$A$11,6) -> 115 | C9: =B9-B10 -> 20 | D9: =SUMPRODUCT(--('Entradas'!$E$11:$E$14="HOT"),--('Entradas'!$J$11:$J$14<=(B9+B10)/2),--('Entradas'!$K$11:$K$14 >=(B9+B10)/2),'Entradas'!$B$11:$B$14) -> 4000 | E9: =SUMPRODUCT(--('Entradas'!$E$11:$E$14="COLD"),--('Entradas'!$J$11:$J$14<=(B9+B10)/2),--('Entradas'!$K$11:$K$14 >=(B9+B10)/2),'Entradas'!$B$11:$B$14) -> 3000 | F9: =D9-E9 -> 1000 | G9: =C9*F9 -> 20000 | H9: =H8+G8 -> -30000 | I9: =H9+'Resumen'!$B$7 -> 40000 | J9: =IF(ABS(I9)<='Resumen'!$B$14,B9,"") | K9: =IF(ISNUMBER(J9),J9+'Entradas'!$B$4/2,"") | L9: =IF(ISNUMBER(J9),J9-'Entradas'!$B$4/2,"") | M9: =IF(ISNUMBER(J9),IF(OR(B9=$B$4,B9=$B$11),"umbral","interior"),"")
A10: ='Entradas'!J14 -> 135 | B10: =LARGE($A$4:$A$11,7) -> 95 | C10: =B10-B11 -> 0 | D10: =SUMPRODUCT(--('Entradas'!$E$11:$E$14="HOT"),--('Entradas'!$J$11:$J$14<=(B10+B11)/2),--('Entradas'!$K$11:$K$14 >=(B10+B11)/2),'Entradas'!$B$11:$B$14) -> 4000 | E10: =SUMPRODUCT(--('Entradas'!$E$11:$E$14="COLD"),--('Entradas'!$J$11:$J$14<=(B10+B11)/2),--('Entradas'!$K$11:$K$14 >=(B10+B11)/2),'Entradas'!$B$11:$B$14) -> 3000 | F10: =D10-E10 -> 1000 | G10: =C10*F10 -> 0 | H10: =H9+G9 -> -10000 | I10: =H10+'Resumen'!$B$7 -> 60000 | J10: =IF(ABS(I10)<='Resumen'!$B$14,B10,"") | K10: =IF(ISNUMBER(J10),J10+'Entradas'!$B$4/2,"") | L10: =IF(ISNUMBER(J10),J10-'Entradas'!$B$4/2,"") | M10: =IF(ISNUMBER(J10),IF(OR(B10=$B$4,B10=$B$11),"umbral","interior"),"")
A11: ='Entradas'!K14 -> 195 | B11: =LARGE($A$4:$A$11,8) -> 95 | H11: =H10+G10 -> -10000 | I11: =H11+'Resumen'!$B$7 -> 60000 | J11: =IF(ABS(I11)<='Resumen'!$B$14,B11,"") | K11: =IF(ISNUMBER(J11),J11+'Entradas'!$B$4/2,"") | L11: =IF(ISNUMBER(J11),J11-'Entradas'!$B$4/2,"") | M11: =IF(ISNUMBER(J11),IF(OR(B11=$B$4,B11=$B$11),"umbral","interior"),"")

Sheet Compuestas
A1: Integración de las curvas compuestas
A2: Hhot inicia en 0. Hcold se desplaza QCmin. Segmentos verticales interiores indican huecos sin carga.
A3: T sin ordenar | B3: T ascendente | C3: T media | D3: ΣCP hot | E3: ΣCP cold | F3: ΔH hot | G3: ΔH cold | H3: H hot | I3: H cold origen | J3: H cold ajustada | K3: T hot gráfico | L3: T cold gráfico | M3: T* hot | N3: T* cold | O3: Índice tramo
A4: ='Entradas'!H11 -> 120 | B4: =SMALL($A$4:$A$11,1) -> 90 | C4: =(B4+B5)/2 -> 95 | D4: =SUMPRODUCT(--('Entradas'!$E$11:$E$14="HOT"),--('Entradas'!$H$11:$H$14<=C4),--('Entradas'!$I$11:$I$14>=C4),'Entradas'!$B$11:$B$14) -> 0 | E4: =SUMPRODUCT(--('Entradas'!$E$11:$E$14="COLD"),--('Entradas'!$H$11:$H$14<=C4),--('Entradas'!$I$11:$I$14>=C4),'Entradas'!$B$11:$B$14) -> 3000 | F4: =D4*(B5-B4) -> 0 | G4: =E4*(B5-B4) -> 30000 | H4: =0 -> 0 | I4: =0 -> 0 | J4: =I4+'Resumen'!$B$8 -> 60000 | K4: =IF(OR(H5>H4),B4,"") | L4: =IF(OR(I5>I4),B4,"") -> 90 | M4: =IF(ISNUMBER(K4),K4+-1*'Entradas'!$B$4/2,"") | N4: =IF(ISNUMBER(L4),L4+1*'Entradas'!$B$4/2,"") -> 95 | O4: 1
A5: ='Entradas'!I11 -> 250 | B5: =SMALL($A$4:$A$11,2) -> 100 | C5: =(B5+B6)/2 -> 110 | D5: =SUMPRODUCT(--('Entradas'!$E$11:$E$14="HOT"),--('Entradas'!$H$11:$H$14<=C5),--('Entradas'!$I$11:$I$14>=C5),'Entradas'!$B$11:$B$14) -> 4000 | E5: =SUMPRODUCT(--('Entradas'!$E$11:$E$14="COLD"),--('Entradas'!$H$11:$H$14<=C5),--('Entradas'!$I$11:$I$14>=C5),'Entradas'!$B$11:$B$14) -> 3000 | F5: =D5*(B6-B5) -> 80000 | G5: =E5*(B6-B5) -> 60000 | H5: =H4+F4 -> 0 | I5: =I4+G4 -> 30000 | J5: =I5+'Resumen'!$B$8 -> 90000 | K5: =IF(OR(H5>H4,H6>H5),B5,"") -> 100 | L5: =IF(OR(I5>I4,I6>I5),B5,"") -> 100 | M5: =IF(ISNUMBER(K5),K5+-1*'Entradas'!$B$4/2,"") -> 95 | N5: =IF(ISNUMBER(L5),L5+1*'Entradas'!$B$4/2,"") -> 105 | O5: 2
A6: ='Entradas'!H12 -> 100 | B6: =SMALL($A$4:$A$11,3) -> 120 | C6: =(B6+B7)/2 -> 125 | D6: =SUMPRODUCT(--('Entradas'!$E$11:$E$14="HOT"),--('Entradas'!$H$11:$H$14<=C6),--('Entradas'!$I$11:$I$14>=C6),'Entradas'!$B$11:$B$14) -> 5000 | E6: =SUMPRODUCT(--('Entradas'!$E$11:$E$14="COLD"),--('Entradas'!$H$11:$H$14<=C6),--('Entradas'!$I$11:$I$14>=C6),'Entradas'!$B$11:$B$14) -> 3000 | F6: =D6*(B7-B6) -> 50000 | G6: =E6*(B7-B6) -> 30000 | H6: =H5+F5 -> 80000 | I6: =I5+G5 -> 90000 | J6: =I6+'Resumen'!$B$8 -> 150000 | K6: =IF(OR(H6>H5,H7>H6),B6,"") -> 120 | L6: =IF(OR(I6>I5,I7>I6),B6,"") -> 120 | M6: =IF(ISNUMBER(K6),K6+-1*'Entradas'!$B$4/2,"") -> 115 | N6: =IF(ISNUMBER(L6),L6+1*'Entradas'!$B$4/2,"") -> 125 | O6: 3
A7: ='Entradas'!I12 -> 200 | B7: =SMALL($A$4:$A$11,4) -> 130 | C7: =(B7+B8)/2 -> 140 | D7: =SUMPRODUCT(--('Entradas'!$E$11:$E$14="HOT"),--('Entradas'!$H$11:$H$14<=C7),--('Entradas'!$I$11:$I$14>=C7),'Entradas'!$B$11:$B$14) -> 5000 | E7: =SUMPRODUCT(--('Entradas'!$E$11:$E$14="COLD"),--('Entradas'!$H$11:$H$14<=C7),--('Entradas'!$I$11:$I$14>=C7),'Entradas'!$B$11:$B$14) -> 9000 | F7: =D7*(B8-B7) -> 100000 | G7: =E7*(B8-B7) -> 180000 | H7: =H6+F6 -> 130000 | I7: =I6+G6 -> 120000 | J7: =I7+'Resumen'!$B$8 -> 180000 | K7: =IF(OR(H7>H6,H8>H7),B7,"") -> 130 | L7: =IF(OR(I7>I6,I8>I7),B7,"") -> 130 | M7: =IF(ISNUMBER(K7),K7+-1*'Entradas'!$B$4/2,"") -> 125 | N7: =IF(ISNUMBER(L7),L7+1*'Entradas'!$B$4/2,"") -> 135 | O7: 4
A8: ='Entradas'!H13 -> 90 | B8: =SMALL($A$4:$A$11,5) -> 150 | C8: =(B8+B9)/2 -> 170 | D8: =SUMPRODUCT(--('Entradas'!$E$11:$E$14="HOT"),--('Entradas'!$H$11:$H$14<=C8),--('Entradas'!$I$11:$I$14>=C8),'Entradas'!$B$11:$B$14) -> 5000 | E8: =SUMPRODUCT(--('Entradas'!$E$11:$E$14="COLD"),--('Entradas'!$H$11:$H$14<=C8),--('Entradas'!$I$11:$I$14>=C8),'Entradas'!$B$11:$B$14) -> 6000 | F8: =D8*(B9-B8) -> 200000 | G8: =E8*(B9-B8) -> 240000 | H8: =H7+F7 -> 230000 | I8: =I7+G7 -> 300000 | J8: =I8+'Resumen'!$B$8 -> 360000 | K8: =IF(OR(H8>H7,H9>H8),B8,"") -> 150 | L8: =IF(OR(I8>I7,I9>I8),B8,"") -> 150 | M8: =IF(ISNUMBER(K8),K8+-1*'Entradas'!$B$4/2,"") -> 145 | N8: =IF(ISNUMBER(L8),L8+1*'Entradas'!$B$4/2,"") -> 155 | O8: 5
A9: ='Entradas'!I13 -> 150 | B9: =SMALL($A$4:$A$11,6) -> 190 | C9: =(B9+B10)/2 -> 195 | D9: =SUMPRODUCT(--('Entradas'!$E$11:$E$14="HOT"),--('Entradas'!$H$11:$H$14<=C9),--('Entradas'!$I$11:$I$14>=C9),'Entradas'!$B$11:$B$14) -> 5000 | E9: =SUMPRODUCT(--('Entradas'!$E$11:$E$14="COLD"),--('Entradas'!$H$11:$H$14<=C9),--('Entradas'!$I$11:$I$14>=C9),'Entradas'!$B$11:$B$14) -> 0 | F9: =D9*(B10-B9) -> 50000 | G9: =E9*(B10-B9) -> 0 | H9: =H8+F8 -> 430000 | I9: =I8+G8 -> 540000 | J9: =I9+'Resumen'!$B$8 -> 600000 | K9: =IF(OR(H9>H8,H10>H9),B9,"") -> 190 | L9: =IF(OR(I9>I8,I10>I9),B9,"") -> 190 | M9: =IF(ISNUMBER(K9),K9+-1*'Entradas'!$B$4/2,"") -> 185 | N9: =IF(ISNUMBER(L9),L9+1*'Entradas'!$B$4/2,"") -> 195 | O9: 6
A10: ='Entradas'!H14 -> 130 | B10: =SMALL($A$4:$A$11,7) -> 200 | C10: =(B10+B11)/2 -> 225 | D10: =SUMPRODUCT(--('Entradas'!$E$11:$E$14="HOT"),--('Entradas'!$H$11:$H$14<=C10),--('Entradas'!$I$11:$I$14>=C10),'Entradas'!$B$11:$B$14) -> 1000 | E10: =SUMPRODUCT(--('Entradas'!$E$11:$E$14="COLD"),--('Entradas'!$H$11:$H$14<=C10),--('Entradas'!$I$11:$I$14>=C10),'Entradas'!$B$11:$B$14) -> 0 | F10: =D10*(B11-B10) -> 50000 | G10: =E10*(B11-B10) -> 0 | H10: =H9+F9 -> 480000 | I10: =I9+G9 -> 540000 | J10: =I10+'Resumen'!$B$8 -> 600000 | K10: =IF(OR(H10>H9,H11>H10),B10,"") -> 200 | L10: =IF(OR(I10>I9,I11>I10),B10,"") | M10: =IF(ISNUMBER(K10),K10+-1*'Entradas'!$B$4/2,"") -> 195 | N10: =IF(ISNUMBER(L10),L10+1*'Entradas'!$B$4/2,"") | O10: 7
A11: ='Entradas'!I14 -> 190 | B11: =SMALL($A$4:$A$11,8) -> 250 | H11: =H10+F10 -> 530000 | I11: =I10+G10 -> 540000 | J11: =I11+'Resumen'!$B$8 -> 600000 | K11: =IF(OR(H11>H10),B11,"") -> 250 | L11: =IF(OR(I11>I10),B11,"") | M11: =IF(ISNUMBER(K11),K11+-1*'Entradas'!$B$4/2,"") -> 245 | N11: =IF(ISNUMBER(L11),L11+1*'Entradas'!$B$4/2,"")
A16: Corriente | B16: H local | C16: T real
A17: ='Entradas'!A11 -> H1 | B17: =IF('Entradas'!E11="HOT",1,0)*'Entradas'!F11 -> 130000 | C17: ='Entradas'!C11 -> 250
A18: ='Entradas'!A11 -> H1 | B18: =IF('Entradas'!E11="HOT",0,1)*'Entradas'!F11 -> 0 | C18: ='Entradas'!D11 -> 120
A19: ='Entradas'!A12 -> H2 | B19: =IF('Entradas'!E12="HOT",1,0)*'Entradas'!F12 -> 400000 | C19: ='Entradas'!C12 -> 200
A20: ='Entradas'!A12 -> H2 | B20: =IF('Entradas'!E12="HOT",0,1)*'Entradas'!F12 -> 0 | C20: ='Entradas'!D12 -> 100
A21: ='Entradas'!A13 -> C3 | B21: =IF('Entradas'!E13="HOT",1,0)*'Entradas'!F13 -> 0 | C21: ='Entradas'!C13 -> 90
A22: ='Entradas'!A13 -> C3 | B22: =IF('Entradas'!E13="HOT",0,1)*'Entradas'!F13 -> 180000 | C22: ='Entradas'!D13 -> 150
A23: ='Entradas'!A14 -> C4 | B23: =IF('Entradas'!E14="HOT",1,0)*'Entradas'!F14 -> 0 | C23: ='Entradas'!C14 -> 130
A24: ='Entradas'!A14 -> C4 | B24: =IF('Entradas'!E14="HOT",0,1)*'Entradas'!F14 -> 360000 | C24: ='Entradas'!D14 -> 190

Sheet Tramos_red
A1: Tramos de intercambio y división de corrientes
A2: Cada tramo tiene un intervalo de temperaturas caliente y frío. Las fracciones CP definen las ramas.
A3: H sin ordenar | B3: H ordenada | C3: ΔH tramo | D3: H media | E3: Índice hot | F3: Índice cold | G3: CP hot | H3: CP cold | I3: Th baja | J3: Th alta | K3: Tc baja | L3: Tc alta | M3: Q proceso | N3: Q refrigeración | O3: Q calentamiento | P3: ΔT extremo 1 | Q3: ΔT extremo 2 | R3: ΔT log media | S3: Área proceso | T3: fh H1 | U3: fh H2 | V3: fh C3 | W3: fh C4 | X3: fc H1 | Y3: fc H2 | Z3: fc C3 | AA3: fc C4
A4: ='Compuestas'!H4 -> 0 | B4: =SMALL($A$4:$A$19,1) -> 0 | C4: =B5-B4 -> 0 | D4: =(B4+B5)/2 -> 0 | E4: =IF(C4<='Resumen'!$B$14,0,SUMPRODUCT(--('Compuestas'!$H$4:$H$10<=D4),--('Compuestas'!$H$5:$H$11>D4),'Compuestas'!$O$4:$O$10)) -> 0 | F4: =IF(C4<='Resumen'!$B$14,0,SUMPRODUCT(--('Compuestas'!$J$4:$J$10<=D4),--('Compuestas'!$J$5:$J$11>D4),'Compuestas'!$O$4:$O$10)) -> 0 | G4: =IF(E4>0,INDEX('Compuestas'!$D$4:$D$10,E4),0) -> 0 | H4: =IF(F4>0,INDEX('Compuestas'!$E$4:$E$10,F4),0) -> 0 | I4: =IF(E4>0,INDEX('Compuestas'!$B$4:$B$10,E4)+(B4-INDEX('Compuestas'!$H$4:$H$10,E4))/G4,0) -> 0 | J4: =IF(E4>0,INDEX('Compuestas'!$B$4:$B$10,E4)+(B5-INDEX('Compuestas'!$H$4:$H$10,E4))/G4,0) -> 0 | K4: =IF(F4>0,INDEX('Compuestas'!$B$4:$B$10,F4)+(B4-INDEX('Compuestas'!$J$4:$J$10,F4))/H4,0) -> 0 | L4: =IF(F4>0,INDEX('Compuestas'!$B$4:$B$10,F4)+(B5-INDEX('Compuestas'!$J$4:$J$10,F4))/H4,0) -> 0 | M4: =IF(AND(E4>0,F4>0),C4,0) -> 0 | N4: =IF(AND(E4>0,F4=0),C4,0) -> 0 | O4: =IF(AND(E4=0,F4>0),C4,0) -> 0 | P4: =IF(M4>0,J4-L4,0) -> 0 | Q4: =IF(M4>0,I4-K4,0) -> 0 | R4: =IF(M4=0,0,IF(MIN(P4,Q4)<=0,0,IF(ABS(P4-Q4)<0.00000001,(P4+Q4)/2,(P4-Q4)/LN(P4/Q4)))) -> 0 | S4: =IF(M4=0,0,IF('Entradas'!$B$5=0,"sin U",IF(R4=0,"infinita",M4/('Entradas'!$B$5*R4)))) -> 0 | T4: =IF(AND(E4>0,'Entradas'!E11="HOT",'Entradas'!H11<=(I4+J4)/2,'Entradas'!I11>=(I4+J4)/2),'Entradas'!B11/G4,0) -> 0 | U4: =IF(AND(E4>0,'Entradas'!E12="HOT",'Entradas'!H12<=(I4+J4)/2,'Entradas'!I12>=(I4+J4)/2),'Entradas'!B12/G4,0) -> 0 | V4: =IF(AND(E4>0,'Entradas'!E13="HOT",'Entradas'!H13<=(I4+J4)/2,'Entradas'!I13>=(I4+J4)/2),'Entradas'!B13/G4,0) -> 0 | W4: =IF(AND(E4>0,'Entradas'!E14="HOT",'Entradas'!H14<=(I4+J4)/2,'Entradas'!I14>=(I4+J4)/2),'Entradas'!B14/G4,0) -> 0 | X4: =IF(AND(F4>0,'Entradas'!E11="COLD",'Entradas'!H11<=(K4+L4)/2,'Entradas'!I11>=(K4+L4)/2),'Entradas'!B11/H4,0) -> 0 | Y4: =IF(AND(F4>0,'Entradas'!E12="COLD",'Entradas'!H12<=(K4+L4)/2,'Entradas'!I12>=(K4+L4)/2),'Entradas'!B12/H4,0) -> 0 | Z4: =IF(AND(F4>0,'Entradas'!E13="COLD",'Entradas'!H13<=(K4+L4)/2,'Entradas'!I13>=(K4+L4)/2),'Entradas'!B13/H4,0) -> 0 | AA4: =IF(AND(F4>0,'Entradas'!E14="COLD",'Entradas'!H14<=(K4+L4)/2,'Entradas'!I14>=(K4+L4)/2),'Entradas'!B14/H4,0) -> 0
A5: ='Compuestas'!H5 -> 0 | B5: =SMALL($A$4:$A$19,2) -> 0 | C5: =B6-B5 -> 60000 | D5: =(B5+B6)/2 -> 30000 | E5: =IF(C5<='Resumen'!$B$14,0,SUMPRODUCT(--('Compuestas'!$H$4:$H$10<=D5),--('Compuestas'!$H$5:$H$11>D5),'Compuestas'!$O$4:$O$10)) -> 2 | F5: =IF(C5<='Resumen'!$B$14,0,SUMPRODUCT(--('Compuestas'!$J$4:$J$10<=D5),--('Compuestas'!$J$5:$J$11>D5),'Compuestas'!$O$4:$O$10)) -> 0 | G5: =IF(E5>0,INDEX('Compuestas'!$D$4:$D$10,E5),0) -> 4000 | H5: =IF(F5>0,INDEX('Compuestas'!$E$4:$E$10,F5),0) -> 0 | I5: =IF(E5>0,INDEX('Compuestas'!$B$4:$B$10,E5)+(B5-INDEX('Compuestas'!$H$4:$H$10,E5))/G5,0) -> 100 | J5: =IF(E5>0,INDEX('Compuestas'!$B$4:$B$10,E5)+(B6-INDEX('Compuestas'!$H$4:$H$10,E5))/G5,0) -> 115 | K5: =IF(F5>0,INDEX('Compuestas'!$B$4:$B$10,F5)+(B5-INDEX('Compuestas'!$J$4:$J$10,F5))/H5,0) -> 0 | L5: =IF(F5>0,INDEX('Compuestas'!$B$4:$B$10,F5)+(B6-INDEX('Compuestas'!$J$4:$J$10,F5))/H5,0) -> 0 | M5: =IF(AND(E5>0,F5>0),C5,0) -> 0 | N5: =IF(AND(E5>0,F5=0),C5,0) -> 60000 | O5: =IF(AND(E5=0,F5>0),C5,0) -> 0 | P5: =IF(M5>0,J5-L5,0) -> 0 | Q5: =IF(M5>0,I5-K5,0) -> 0 | R5: =IF(M5=0,0,IF(MIN(P5,Q5)<=0,0,IF(ABS(P5-Q5)<0.00000001,(P5+Q5)/2,(P5-Q5)/LN(P5/Q5)))) -> 0 | S5: =IF(M5=0,0,IF('Entradas'!$B$5=0,"sin U",IF(R5=0,"infinita",M5/('Entradas'!$B$5*R5)))) -> 0 | T5: =IF(AND(E5>0,'Entradas'!E11="HOT",'Entradas'!H11<=(I5+J5)/2,'Entradas'!I11>=(I5+J5)/2),'Entradas'!B11/G5,0) -> 0 | U5: =IF(AND(E5>0,'Entradas'!E12="HOT",'Entradas'!H12<=(I5+J5)/2,'Entradas'!I12>=(I5+J5)/2),'Entradas'!B12/G5,0) -> 1 | V5: =IF(AND(E5>0,'Entradas'!E13="HOT",'Entradas'!H13<=(I5+J5)/2,'Entradas'!I13>=(I5+J5)/2),'Entradas'!B13/G5,0) -> 0 | W5: =IF(AND(E5>0,'Entradas'!E14="HOT",'Entradas'!H14<=(I5+J5)/2,'Entradas'!I14>=(I5+J5)/2),'Entradas'!B14/G5,0) -> 0 | X5: =IF(AND(F5>0,'Entradas'!E11="COLD",'Entradas'!H11<=(K5+L5)/2,'Entradas'!I11>=(K5+L5)/2),'Entradas'!B11/H5,0) -> 0 | Y5: =IF(AND(F5>0,'Entradas'!E12="COLD",'Entradas'!H12<=(K5+L5)/2,'Entradas'!I12>=(K5+L5)/2),'Entradas'!B12/H5,0) -> 0 | Z5: =IF(AND(F5>0,'Entradas'!E13="COLD",'Entradas'!H13<=(K5+L5)/2,'Entradas'!I13>=(K5+L5)/2),'Entradas'!B13/H5,0) -> 0 | AA5: =IF(AND(F5>0,'Entradas'!E14="COLD",'Entradas'!H14<=(K5+L5)/2,'Entradas'!I14>=(K5+L5)/2),'Entradas'!B14/H5,0) -> 0
A6: ='Compuestas'!H6 -> 80000 | B6: =SMALL($A$4:$A$19,3) -> 60000 | C6: =B7-B6 -> 20000 | D6: =(B6+B7)/2 -> 70000 | E6: =IF(C6<='Resumen'!$B$14,0,SUMPRODUCT(--('Compuestas'!$H$4:$H$10<=D6),--('Compuestas'!$H$5:$H$11>D6),'Compuestas'!$O$4:$O$10)) -> 2 | F6: =IF(C6<='Resumen'!$B$14,0,SUMPRODUCT(--('Compuestas'!$J$4:$J$10<=D6),--('Compuestas'!$J$5:$J$11>D6),'Compuestas'!$O$4:$O$10)) -> 1 | G6: =IF(E6>0,INDEX('Compuestas'!$D$4:$D$10,E6),0) -> 4000 | H6: =IF(F6>0,INDEX('Compuestas'!$E$4:$E$10,F6),0) -> 3000 | I6: =IF(E6>0,INDEX('Compuestas'!$B$4:$B$10,E6)+(B6-INDEX('Compuestas'!$H$4:$H$10,E6))/G6,0) -> 115 | J6: =IF(E6>0,INDEX('Compuestas'!$B$4:$B$10,E6)+(B7-INDEX('Compuestas'!$H$4:$H$10,E6))/G6,0) -> 120 | K6: =IF(F6>0,INDEX('Compuestas'!$B$4:$B$10,F6)+(B6-INDEX('Compuestas'!$J$4:$J$10,F6))/H6,0) -> 90 | L6: =IF(F6>0,INDEX('Compuestas'!$B$4:$B$10,F6)+(B7-INDEX('Compuestas'!$J$4:$J$10,F6))/H6,0) -> 96.666667 | M6: =IF(AND(E6>0,F6>0),C6,0) -> 20000 | N6: =IF(AND(E6>0,F6=0),C6,0) -> 0 | O6: =IF(AND(E6=0,F6>0),C6,0) -> 0 | P6: =IF(M6>0,J6-L6,0) -> 23.333333 | Q6: =IF(M6>0,I6-K6,0) -> 25 | R6: =IF(M6=0,0,IF(MIN(P6,Q6)<=0,0,IF(ABS(P6-Q6)<0.00000001,(P6+Q6)/2,(P6-Q6)/LN(P6/Q6)))) -> 24.157085 | S6: =IF(M6=0,0,IF('Entradas'!$B$5=0,"sin U",IF(R6=0,"infinita",M6/('Entradas'!$B$5*R6)))) -> sin U | T6: =IF(AND(E6>0,'Entradas'!E11="HOT",'Entradas'!H11<=(I6+J6)/2,'Entradas'!I11>=(I6+J6)/2),'Entradas'!B11/G6,0) -> 0 | U6: =IF(AND(E6>0,'Entradas'!E12="HOT",'Entradas'!H12<=(I6+J6)/2,'Entradas'!I12>=(I6+J6)/2),'Entradas'!B12/G6,0) -> 1 | V6: =IF(AND(E6>0,'Entradas'!E13="HOT",'Entradas'!H13<=(I6+J6)/2,'Entradas'!I13>=(I6+J6)/2),'Entradas'!B13/G6,0) -> 0 | W6: =IF(AND(E6>0,'Entradas'!E14="HOT",'Entradas'!H14<=(I6+J6)/2,'Entradas'!I14>=(I6+J6)/2),'Entradas'!B14/G6,0) -> 0 | X6: =IF(AND(F6>0,'Entradas'!E11="COLD",'Entradas'!H11<=(K6+L6)/2,'Entradas'!I11>=(K6+L6)/2),'Entradas'!B11/H6,0) -> 0 | Y6: =IF(AND(F6>0,'Entradas'!E12="COLD",'Entradas'!H12<=(K6+L6)/2,'Entradas'!I12>=(K6+L6)/2),'Entradas'!B12/H6,0) -> 0 | Z6: =IF(AND(F6>0,'Entradas'!E13="COLD",'Entradas'!H13<=(K6+L6)/2,'Entradas'!I13>=(K6+L6)/2),'Entradas'!B13/H6,0) -> 1 | AA6: =IF(AND(F6>0,'Entradas'!E14="COLD",'Entradas'!H14<=(K6+L6)/2,'Entradas'!I14>=(K6+L6)/2),'Entradas'!B14/H6,0) -> 0
A7: ='Compuestas'!H7 -> 130000 | B7: =SMALL($A$4:$A$19,4) -> 80000 | C7: =B8-B7 -> 10000 | D7: =(B7+B8)/2 -> 85000 | E7: =IF(C7<='Resumen'!$B$14,0,SUMPRODUCT(--('Compuestas'!$H$4:$H$10<=D7),--('Compuestas'!$H$5:$H$11>D7),'Compuestas'!$O$4:$O$10)) -> 3 | F7: =IF(C7<='Resumen'!$B$14,0,SUMPRODUCT(--('Compuestas'!$J$4:$J$10<=D7),--('Compuestas'!$J$5:$J$11>D7),'Compuestas'!$O$4:$O$10)) -> 1 | G7: =IF(E7>0,INDEX('Compuestas'!$D$4:$D$10,E7),0) -> 5000 | H7: =IF(F7>0,INDEX('Compuestas'!$E$4:$E$10,F7),0) -> 3000 | I7: =IF(E7>0,INDEX('Compuestas'!$B$4:$B$10,E7)+(B7-INDEX('Compuestas'!$H$4:$H$10,E7))/G7,0) -> 120 | J7: =IF(E7>0,INDEX('Compuestas'!$B$4:$B$10,E7)+(B8-INDEX('Compuestas'!$H$4:$H$10,E7))/G7,0) -> 122 | K7: =IF(F7>0,INDEX('Compuestas'!$B$4:$B$10,F7)+(B7-INDEX('Compuestas'!$J$4:$J$10,F7))/H7,0) -> 96.666667 | L7: =IF(F7>0,INDEX('Compuestas'!$B$4:$B$10,F7)+(B8-INDEX('Compuestas'!$J$4:$J$10,F7))/H7,0) -> 100 | M7: =IF(AND(E7>0,F7>0),C7,0) -> 10000 | N7: =IF(AND(E7>0,F7=0),C7,0) -> 0 | O7: =IF(AND(E7=0,F7>0),C7,0) -> 0 | P7: =IF(M7>0,J7-L7,0) -> 22 | Q7: =IF(M7>0,I7-K7,0) -> 23.333333 | R7: =IF(M7=0,0,IF(MIN(P7,Q7)<=0,0,IF(ABS(P7-Q7)<0.00000001,(P7+Q7)/2,(P7-Q7)/LN(P7/Q7)))) -> 22.660129 | S7: =IF(M7=0,0,IF('Entradas'!$B$5=0,"sin U",IF(R7=0,"infinita",M7/('Entradas'!$B$5*R7)))) -> sin U | T7: =IF(AND(E7>0,'Entradas'!E11="HOT",'Entradas'!H11<=(I7+J7)/2,'Entradas'!I11>=(I7+J7)/2),'Entradas'!B11/G7,0) -> 0.2 | U7: =IF(AND(E7>0,'Entradas'!E12="HOT",'Entradas'!H12<=(I7+J7)/2,'Entradas'!I12>=(I7+J7)/2),'Entradas'!B12/G7,0) -> 0.8 | V7: =IF(AND(E7>0,'Entradas'!E13="HOT",'Entradas'!H13<=(I7+J7)/2,'Entradas'!I13>=(I7+J7)/2),'Entradas'!B13/G7,0) -> 0 | W7: =IF(AND(E7>0,'Entradas'!E14="HOT",'Entradas'!H14<=(I7+J7)/2,'Entradas'!I14>=(I7+J7)/2),'Entradas'!B14/G7,0) -> 0 | X7: =IF(AND(F7>0,'Entradas'!E11="COLD",'Entradas'!H11<=(K7+L7)/2,'Entradas'!I11>=(K7+L7)/2),'Entradas'!B11/H7,0) -> 0 | Y7: =IF(AND(F7>0,'Entradas'!E12="COLD",'Entradas'!H12<=(K7+L7)/2,'Entradas'!I12>=(K7+L7)/2),'Entradas'!B12/H7,0) -> 0 | Z7: =IF(AND(F7>0,'Entradas'!E13="COLD",'Entradas'!H13<=(K7+L7)/2,'Entradas'!I13>=(K7+L7)/2),'Entradas'!B13/H7,0) -> 1 | AA7: =IF(AND(F7>0,'Entradas'!E14="COLD",'Entradas'!H14<=(K7+L7)/2,'Entradas'!I14>=(K7+L7)/2),'Entradas'!B14/H7,0) -> 0
